File: Result/Raw data/XRD_550C_raw/CSV files/Cu-30min-550C-Striped-KAlpha2.csv
[Measurement conditions]
Sample identification,
Comment - 1,"Configuration=Flat Sample Stage, Owner=User-1, Creation date=3/25/2015 2:10:01 PM"
Comment - 2,"Goniometer=PW3050/60 (Theta/Theta); Minimum step size 2Theta:0.001; Minimum step size Omega:0.001"
Comment - 3,"Sample stage=PW3071/xx Bracket"
Comment - 4,"Diffractometer system=XPERT-PRO"
Comment - 5,"Measurement program=C:\PANalytical\Data Collector\Programs\Flat sample Scan.xrdmp, Identifier={A9F6D0C0-202E-4C59-A4F1-A5BA86123012}"
Comment - 6,""
Anode material,Cu
K-Alpha1 wavelength,1.5405980
K-Alpha2 wavelength,1.5444260
Ratio K-Alpha2/K-Alpha1,0.000
Divergence slit,Fixed,0.500
Receiving slit,0.10
Monochromator used,NO
Generator voltage, 40
Tube current, 30
File date and time,27/Feb/2020 18:09
Unit cell,
h k l, 0 0 0
Temperature [K],298
Scan axis,Gonio
Scan range,19.9995,79.9925
Scan step size,0.0170000
No. of points, 3529
Scan type,CONTINUOUS
Time per step,34.925
[Scan points]
Angle,Intensity
20.0090,989.1
20.0600,1007.5
20.1110,1030.5
20.1620,1025.9
20.2130,1022.0
20.2640,1053.6
20.3150,1023.2
20.3660,1051.9
20.4170,1013.5
20.4680,1051.5
20.5190,998.6
20.5700,1005.2
20.6210,1052.6
20.6720,1021.3
20.7230,1067.5
20.7740,1038.0
20.8250,1028.9
20.8760,1039.4
20.9270,1032.1
20.9780,1019.4
21.0290,1054.6
21.0800,1069.1
21.1310,1014.6
21.1820,1029.6
21.2330,1046.8
21.2840,1057.6
21.3350,1039.6
21.3860,1037.2
21.4370,1063.2
21.4880,1048.1
21.5390,1062.1
21.5900,1057.2
21.6410,1086.2
21.6920,1034.8
21.7430,1033.1
21.7940,1066.9
21.8450,1053.6
21.8960,1077.6
21.9470,1053.1
21.9980,1083.2
22.0490,1044.4
22.1000,1070.4
22.1510,1043.9
22.2020,1116.2
22.2530,1083.3
22.3040,1131.7
22.3550,1067.9
22.4060,1100.4
22.4570,1080.1
22.5080,1079.4
22.5590,1082.8
22.6100,1103.7
22.6610,1072.7
22.7120,1090.1
22.7630,1109.6
22.8140,1080.1
22.8650,1101.1
22.9160,1102.4
22.9670,1091.1
23.0180,1115.1
23.0690,1121.1
23.1200,1060.5
23.1710,1082.8
23.2220,1077.6
23.2730,1112.4
23.3240,1064.5
23.3750,1084.6
23.4260,1066.9
23.4770,1115.8
23.5280,1108.5
23.5790,1078.7
23.6300,1080.6
23.6810,1128.9
23.7320,1136.5
23.7830,1128.1
23.8340,1147.0
23.8850,1114.4
23.9360,1162.7
23.9870,1116.2
24.0380,1120.2
24.0890,1116.1
24.1400,1118.5
24.1910,1154.3
24.2420,1123.4
24.2930,1148.7
24.3440,1174.4
24.3950,1144.1
24.4460,1137.5
24.4970,1138.4
24.5480,1128.4
24.5990,1130.9
24.6500,1137.6
24.7010,1125.8
24.7520,1100.9
24.8030,1107.9
24.8540,1130.4
24.9050,1168.6
24.9560,1145.6
25.0070,1125.6
25.0580,1150.6
25.1090,1147.2
25.1600,1150.0
25.2110,1160.5
25.2620,1158.4
25.3130,1181.6
25.3640,1112.8
25.4150,1156.6
25.4660,1187.9
25.5170,1173.5
25.5680,1174.4
25.6190,1162.0
25.6700,1162.6
25.7210,1173.5
25.7720,1213.4
25.8230,1141.0
25.8740,1220.8
25.9250,1173.3
25.9760,1199.3
26.0270,1153.1
26.0780,1177.6
26.1290,1183.4
26.1800,1167.5
26.2310,1164.2
26.2820,1168.4
26.3330,1205.4
26.3840,1189.4
26.4350,1193.3
26.4860,1174.1
26.5370,1157.0
26.5880,1186.8
26.6390,1188.4
26.6900,1174.8
26.7410,1199.7
26.7920,1142.6
26.8430,1146.6
26.8940,1191.6
26.9450,1222.0
26.9960,1227.4
27.0470,1201.4
27.0980,1244.4
27.1490,1175.4
27.2000,1215.5
27.2510,1180.6
27.3020,1220.1
27.3530,1167.6
27.4040,1236.6
27.4550,1195.5
27.5060,1199.3
27.5570,1241.1
27.6080,1204.2
27.6590,1160.8
27.7100,1215.8
27.7610,1166.9
27.8120,1208.8
27.8630,1206.5
27.9140,1217.9
27.9650,1153.9
28.0160,1208.8
28.0670,1183.7
28.1180,1218.3
28.1690,1200.9
28.2200,1228.9
28.2710,1188.4
28.3220,1228.9
28.3730,1194.0
28.4240,1223.3
28.4750,1264.9
28.5260,1241.7
28.5770,1252.6
28.6280,1242.6
28.6790,1229.9
28.7300,1202.3
28.7810,1273.3
28.8320,1269.7
28.8830,1222.6
28.9340,1201.8
28.9850,1283.3
29.0360,1281.1
29.0870,1285.6
29.1380,1237.5
29.1890,1253.2
29.2400,1220.6
29.2910,1266.2
29.3420,1231.8
29.3930,1242.9
29.4440,1237.8
29.4950,1276.6
29.5460,1251.9
29.5970,1269.7
29.6480,1208.8
29.6990,1272.3
29.7500,1239.0
29.8010,1281.5
29.8520,1266.3
29.9030,1264.0
29.9540,1258.6
30.0050,1257.2
30.0560,1277.1
30.1070,1291.6
30.1580,1243.9
30.2090,1279.1
30.2600,1272.1
30.3110,1281.8
30.3620,1273.6
30.4130,1292.4
30.4640,1272.9
30.5150,1245.8
30.5660,1250.1
30.6170,1239.6
30.6680,1258.6
30.7190,1299.0
30.7700,1247.5
30.8210,1293.6
30.8720,1279.9
30.9230,1271.8
30.9740,1286.2
31.0250,1256.9
31.0760,1274.8
31.1270,1271.8
31.1780,1327.2
31.2290,1289.7
31.2800,1270.2
31.3310,1307.2
31.3820,1299.1
31.4330,1277.8
31.4840,1329.5
31.5350,1271.1
31.5860,1313.4
31.6370,1272.5
31.6880,1301.5
31.7390,1304.4
31.7900,1321.4
31.8410,1305.9
31.8920,1239.2
31.9430,1273.8
31.9940,1257.1
32.0450,1271.1
32.0960,1312.9
32.1470,1317.2
32.1980,1300.3
32.2490,1275.7
32.3000,1324.6
32.3510,1309.8
32.4020,1307.6
32.4530,1322.1
32.5040,1310.2
32.5550,1348.7
32.6060,1283.8
32.6570,1309.5
32.7080,1323.4
32.7590,1328.6
32.8100,1332.9
32.8610,1314.2
32.9120,1356.2
32.9630,1340.4
33.0140,1305.2
33.0650,1336.1
33.1160,1300.5
33.1670,1289.9
33.2180,1333.6
33.2690,1302.6
33.3200,1352.3
33.3710,1302.5
33.4220,1308.4
33.4730,1327.5
33.5240,1298.3
33.5750,1336.2
33.6260,1326.5
33.6770,1299.2
33.7280,1340.3
33.7790,1380.2
33.8300,1313.4
33.8810,1358.5
33.9320,1321.5
33.9830,1269.7
34.0340,1364.5
34.0850,1317.7
34.1360,1340.4
34.1870,1315.9
34.2380,1325.8
34.2890,1319.3
34.3400,1341.8
34.3910,1340.9
34.4420,1322.1
34.4930,1328.4
34.5440,1349.4
34.5950,1294.1
34.6460,1312.5
34.6970,1361.4
34.7480,1369.7
34.7990,1288.4
34.8500,1373.5
34.9010,1297.6
34.9520,1358.9
35.0030,1385.3
35.0540,1324.5
35.1050,1364.8
35.1560,1376.6
35.2070,1347.8
35.2580,1366.5
35.3090,1370.5
35.3600,1360.7
35.4110,1351.8
35.4620,1320.7
35.5130,1370.2
35.5640,1372.5
35.6150,1291.5
35.6660,1404.8
35.7170,1337.4
35.7680,1344.5
35.8190,1381.4
35.8700,1361.6
35.9210,1402.9
35.9720,1408.4
36.0230,1349.8
36.0740,1414.2
36.1250,1346.5
36.1760,1359.2
36.2270,1388.0
36.2780,1367.0
36.3290,1363.1
36.3800,1329.3
36.4310,1372.8
36.4820,1356.1
36.5330,1390.1
36.5840,1401.1
36.6350,1344.2
36.6860,1374.4
36.7370,1351.8
36.7880,1357.2
36.8390,1397.4
36.8900,1357.0
36.9410,1366.4
36.9920,1370.1
37.0430,1351.9
37.0940,1407.6
37.1450,1392.8
37.1960,1357.2
37.2470,1376.8
37.2980,1369.6
37.3490,1378.2
37.4000,1386.6
37.4510,1380.4
37.5020,1401.2
37.5530,1371.9
37.6040,1399.6
37.6550,1415.5
37.7060,1330.9
37.7570,1366.8
37.8080,1418.2
37.8590,1415.0
37.9100,1393.8
37.9610,1364.9
38.0120,1401.2
38.0630,1389.9
38.1140,1424.1
38.1650,1398.6
38.2160,1400.1
38.2670,1369.6
38.3180,1385.1
38.3690,1400.6
38.4200,1372.2
38.4710,1411.5
38.5220,1411.6
38.5730,1367.1
38.6240,1435.6
38.6750,1391.8
38.7260,1453.8
38.7770,1398.1
38.8280,1419.8
38.8790,1437.2
38.9300,1418.7
38.9810,1427.4
39.0320,1444.9
39.0830,1422.1
39.1340,1429.3
39.1850,1384.3
39.2360,1392.6
39.2870,1459.4
39.3380,1432.8
39.3890,1418.5
39.4400,1466.5
39.4910,1443.2
39.5420,1433.5
39.5930,1433.8
39.6440,1418.8
39.6950,1449.9
39.7460,1406.5
39.7970,1398.5
39.8480,1421.6
39.8990,1434.6
39.9500,1418.7
40.0010,1443.3
40.0520,1395.2
40.1030,1446.4
40.1540,1429.7
40.2050,1418.1
40.2560,1449.4
40.3070,1452.2
40.3580,1435.8
40.4090,1390.7
40.4600,1469.2
40.5110,1442.4
40.5620,1421.8
40.6130,1432.4
40.6640,1440.4
40.7150,1479.1
40.7660,1417.8
40.8170,1467.8
40.8680,1450.1
40.9190,1436.5
40.9700,1447.4
41.0210,1451.8
41.0720,1405.6
41.1230,1445.6
41.1740,1467.9
41.2250,1456.3
41.2760,1459.4
41.3270,1461.1
41.3780,1471.0
41.4290,1412.8
41.4800,1546.3
41.5310,1442.4
41.5820,1532.5
41.6330,1431.1
41.6840,1441.9
41.7350,1442.1
41.7860,1527.2
41.8370,1508.0
41.8880,1539.9
41.9390,1501.6
41.9900,1520.9
42.0410,1529.4
42.0920,1494.6
42.1430,1549.6
42.1940,1648.9
42.2450,1526.6
42.2960,1501.6
42.3470,1478.2
42.3980,1550.1
42.4490,1565.8
42.5000,1539.9
42.5510,1529.5
42.6020,1517.4
42.6530,1523.3
42.7040,1556.4
42.7550,1706.1
42.8060,1573.8
42.8570,1569.1
42.9080,1607.5
42.9590,1728.9
43.0100,1825.6
43.0610,2006.1
43.1120,2355.3
43.1630,3220.7
43.2140,6334.6
43.2650,16164.0
43.3160,33013.2
43.3670,16088.9
43.4180,8291.6
43.4690,5340.5
43.5200,3357.9
43.5710,2167.2
43.6220,1888.4
43.6730,1873.3
43.7240,1658.0
43.7750,1552.2
43.8260,1625.4
43.8770,1612.7
43.9280,1577.6
43.9790,1578.5
44.0300,1566.2
44.0810,1568.7
44.1320,1589.4
44.1830,1579.9
44.2340,1597.5
44.2850,1579.8
44.3360,1563.8
44.3870,1551.7
44.4380,1556.9
44.4890,1565.9
44.5400,1497.1
44.5910,1526.4
44.6420,1523.9
44.6930,1559.1
44.7440,1558.9
44.7950,1574.9
44.8460,1570.5
44.8970,1526.7
44.9480,1553.1
44.9990,1560.7
45.0500,1571.6
45.1010,1567.2
45.1520,1546.7
45.2030,1544.5
45.2540,1581.6
45.3050,1713.0
45.3560,1643.1
45.4070,1613.2
45.4580,1526.9
45.5090,1582.1
45.5600,1580.2
45.6110,1573.2
45.6620,1515.3
45.7130,1525.6
45.7640,1568.8
45.8150,1490.9
45.8660,1516.7
45.9170,1510.6
45.9680,1529.3
46.0190,1508.7
46.0700,1546.9
46.1210,1546.8
46.1720,1556.3
46.2230,1498.1
46.2740,1589.8
46.3250,1549.2
46.3760,1551.2
46.4270,1566.5
46.4780,1531.6
46.5290,1552.2
46.5800,1492.6
46.6310,1516.5
46.6820,1540.2
46.7330,1564.7
46.7840,1549.1
46.8350,1534.5
46.8860,1577.3
46.9370,1535.1
46.9880,1566.5
47.0390,1558.1
47.0900,1538.2
47.1410,1552.4
47.1920,1567.4
47.2430,1546.2
47.2940,1513.9
47.3450,1558.9
47.3960,1505.0
47.4470,1545.2
47.4980,1562.8
47.5490,1598.2
47.6000,1490.1
47.6510,1517.4
47.7020,1554.4
47.7530,1553.3
47.8040,1543.6
47.8550,1550.6
47.9060,1555.2
47.9570,1578.9
48.0080,1548.6
48.0590,1542.5
48.1100,1558.8
48.1610,1550.8
48.2120,1532.7
48.2630,1558.1
48.3140,1535.8
48.3650,1609.8
48.4160,1564.8
48.4670,1523.2
48.5180,1584.8
48.5690,1544.1
48.6200,1583.5
48.6710,1632.5
48.7220,1626.2
48.7730,1599.1
48.8240,1669.0
48.8750,1734.5
48.9260,1648.1
48.9770,1669.1
49.0280,1648.9
49.0790,1651.5
49.1300,1676.2
49.1810,1682.2
49.2320,1627.3
49.2830,1676.8
49.3340,1689.4
49.3850,1662.2
49.4360,1661.7
49.4870,1666.8
49.5380,1679.4
49.5890,1683.6
49.6400,1714.5
49.6910,1686.7
49.7420,1724.0
49.7930,1688.6
49.8440,1721.5
49.8950,1741.9
49.9460,1815.5
49.9970,1848.4
50.0480,1893.6
50.0990,2165.6
50.1500,2718.0
50.2010,3212.5
50.2520,3716.1
50.3030,5749.2
50.3540,15551.5
50.4050,49744.4
50.4560,67435.6
50.5070,23370.5
50.5580,8445.1
50.6090,5271.4
50.6600,3579.9
50.7110,2732.9
50.7620,2049.8
50.8130,1951.2
50.8640,1941.4
50.9150,1995.0
50.9660,1730.5
51.0170,1767.3
51.0680,1737.4
51.1190,1838.1
51.1700,1745.4
51.2210,1728.2
51.2720,1695.9
51.3230,1656.1
51.3740,1689.7
51.4250,1709.6
51.4760,1626.2
51.5270,1610.9
51.5780,1695.6
51.6290,1666.6
51.6800,1657.8
51.7310,1604.4
51.7820,1666.2
51.8330,1632.4
51.8840,1588.1
51.9350,1613.8
51.9860,1618.6
52.0370,1585.4
52.0880,1596.5
52.1390,1606.2
52.1900,1638.6
52.2410,1616.0
52.2920,1618.5
52.3430,1579.2
52.3940,1616.7
52.4450,1562.4
52.4960,1574.8
52.5470,1586.2
52.5980,1622.8
52.6490,1582.2
52.7000,1616.5
52.7510,1609.1
52.8020,1605.2
52.8530,1624.0
52.9040,1600.8
52.9550,1582.9
53.0060,1614.6
53.0570,1572.6
53.1080,1614.6
53.1590,1579.4
53.2100,1577.2
53.2610,1584.0
53.3120,1557.2
53.3630,1599.5
53.4140,1622.1
53.4650,1550.2
53.5160,1616.2
53.5670,1565.9
53.6180,1559.1
53.6690,1561.5
53.7200,1579.2
53.7710,1600.2
53.8220,1551.0
53.8730,1573.1
53.9240,1595.6
53.9750,1581.8
54.0260,1567.8
54.0770,1546.5
54.1280,1603.5
54.1790,1609.5
54.2300,1609.4
54.2810,1651.7
54.3320,1570.9
54.3830,1550.5
54.4340,1594.3
54.4850,1527.2
54.5360,1573.0
54.5870,1612.4
54.6380,1557.0
54.6890,1536.1
54.7400,1593.5
54.7910,1623.8
54.8420,1733.5
54.8930,1599.5
54.9440,1612.6
54.9950,1611.9
55.0460,1587.4
55.0970,1580.9
55.1480,1591.8
55.1990,1599.1
55.2500,1513.6
55.3010,1574.8
55.3520,1589.9
55.4030,1498.0
55.4540,1572.9
55.5050,1558.5
55.5560,1596.0
55.6070,1588.4
55.6580,1613.1
55.7090,1564.4
55.7600,1584.5
55.8110,1538.1
55.8620,1591.5
55.9130,1589.0
55.9640,1565.2
56.0150,1502.6
56.0660,1608.2
56.1170,1547.9
56.1680,1609.1
56.2190,1557.6
56.2700,1567.0
56.3210,1587.4
56.3720,1538.3
56.4230,1517.1
56.4740,1555.9
56.5250,1561.1
56.5760,1582.5
56.6270,1553.5
56.6780,1597.8
56.7290,1598.9
56.7800,1559.5
56.8310,1590.8
56.8820,1577.0
56.9330,1598.9
56.9840,1531.1
57.0350,1551.8
57.0860,1599.5
57.1370,1550.6
57.1880,1573.5
57.2390,1559.8
57.2900,1534.8
57.3410,1623.2
57.3920,1560.7
57.4430,1558.1
57.4940,1621.5
57.5450,1566.9
57.5960,1560.5
57.6470,1546.9
57.6980,1495.6
57.7490,1602.4
57.8000,1565.5
57.8510,1532.6
57.9020,1571.6
57.9530,1558.4
58.0040,1586.9
58.0550,1536.2
58.1060,1588.4
58.1570,1629.9
58.2080,1546.5
58.2590,1570.9
58.3100,1532.7
58.3610,1543.1
58.4120,1551.9
58.4630,1575.9
58.5140,1545.9
58.5650,1571.4
58.6160,1536.8
58.6670,1532.4
58.7180,1578.4
58.7690,1542.5
58.8200,1563.9
58.8710,1545.4
58.9220,1561.5
58.9730,1573.9
59.0240,1525.9
59.0750,1532.8
59.1260,1536.7
59.1770,1575.8
59.2280,1545.6
59.2790,1587.8
59.3300,1543.2
59.3810,1532.9
59.4320,1535.3
59.4830,1495.1
59.5340,1560.2
59.5850,1548.9
59.6360,1517.5
59.6870,1559.6
59.7380,1586.2
59.7890,1571.0
59.8400,1571.2
59.8910,1558.2
59.9420,1533.5
59.9930,1531.8
60.0440,1555.0
60.0950,1576.5
60.1460,1600.8
60.1970,1524.4
60.2480,1587.4
60.2990,1533.6
60.3500,1558.1
60.4010,1578.9
60.4520,1548.9
60.5030,1534.2
60.5540,1600.8
60.6050,1542.0
60.6560,1576.0
60.7070,1543.1
60.7580,1564.9
60.8090,1526.0
60.8600,1542.8
60.9110,1540.1
60.9620,1576.7
61.0130,1520.2
61.0640,1542.1
61.1150,1543.1
61.1660,1548.8
61.2170,1515.9
61.2680,1557.9
61.3190,1671.6
61.3700,1572.1
61.4210,1579.1
61.4720,1569.6
61.5230,1587.5
61.5740,1547.1
61.6250,1557.6
61.6760,1563.8
61.7270,1544.1
61.7780,1539.7
61.8290,1579.9
61.8800,1557.5
61.9310,1566.8
61.9820,1562.3
62.0330,1569.1
62.0840,1544.9
62.1350,1574.3
62.1860,1528.6
62.2370,1534.5
62.2880,1483.6
62.3390,1684.2
62.3900,1579.2
62.4410,1533.8
62.4920,1562.8
62.5430,1582.6
62.5940,1555.5
62.6450,1583.1
62.6960,1571.5
62.7470,1560.8
62.7980,1552.8
62.8490,1532.5
62.9000,1540.8
62.9510,1560.2
63.0020,1548.5
63.0530,1579.4
63.1040,1545.8
63.1550,1534.0
63.2060,1581.5
63.2570,1539.6
63.3080,1530.8
63.3590,1552.1
63.4100,1592.9
63.4610,1534.4
63.5120,1586.1
63.5630,1579.1
63.6140,1580.2
63.6650,1606.4
63.7160,1561.3
63.7670,1551.2
63.8180,1576.2
63.8690,1532.1
63.9200,1581.9
63.9710,1523.1
64.0220,1570.2
64.0730,1562.6
64.1240,1615.9
64.1750,1596.8
64.2260,1562.9
64.2770,1605.5
64.3280,1541.5
64.3790,1544.4
64.4300,1584.2
64.4810,1518.6
64.5320,1605.6
64.5830,1569.8
64.6340,1549.5
64.6850,1537.6
64.7360,1607.0
64.7870,1546.2
64.8380,1552.6
64.8890,1600.5
64.9400,1587.6
64.9910,1602.1
65.0420,1536.2
65.0930,1543.8
65.1440,1571.6
65.1950,1555.1
65.2460,1572.1
65.2970,1557.0
65.3480,1528.6
65.3990,1618.7
65.4500,1587.2
65.5010,1596.1
65.5520,1563.1
65.6030,1557.1
65.6540,1528.5
65.7050,1549.8
65.7560,1569.1
65.8070,1549.4
65.8580,1579.2
65.9090,1612.5
65.9600,1594.9
66.0110,1561.1
66.0620,1587.1
66.1130,1584.2
66.1640,1562.5
66.2150,1625.1
66.2660,1618.8
66.3170,1553.1
66.3680,1576.1
66.4190,1571.4
66.4700,1586.6
66.5210,1575.5
66.5720,1568.3
66.6230,1604.0
66.6740,1566.5
66.7250,1574.5
66.7760,1569.2
66.8270,1577.2
66.8780,1578.9
66.9290,1601.8
66.9800,1569.4
67.0310,1553.5
67.0820,1574.4
67.1330,1603.9
67.1840,1549.9
67.2350,1566.1
67.2860,1575.1
67.3370,1591.9
67.3880,1604.2
67.4390,1569.7
67.4900,1582.7
67.5410,1568.1
67.5920,1545.4
67.6430,1555.0
67.6940,1610.5
67.7450,1566.8
67.7960,1579.6
67.8470,1577.2
67.8980,1541.4
67.9490,1570.1
68.0000,1603.4
68.0510,1538.8
68.1020,1597.4
68.1530,1534.2
68.2040,1519.1
68.2550,1593.9
68.3060,1606.6
68.3570,1567.9
68.4080,1586.9
68.4590,1605.5
68.5100,1553.1
68.5610,1568.3
68.6120,1555.6
68.6630,1552.8
68.7140,1627.4
68.7650,1604.3
68.8160,1551.5
68.8670,1585.1
68.9180,1573.0
68.9690,1581.1
69.0200,1513.7
69.0710,1563.5
69.1220,1557.0
69.1730,1595.6
69.2240,1578.7
69.2750,1554.8
69.3260,1546.2
69.3770,1570.5
69.4280,1610.0
69.4790,1598.4
69.5300,1583.0
69.5810,1563.2
69.6320,1585.0
69.6830,1596.6
69.7340,1546.3
69.7850,1580.8
69.8360,1572.5
69.8870,1587.4
69.9380,1593.8
69.9890,1597.4
70.0400,1522.4
70.0910,1597.1
70.1420,1606.7
70.1930,1613.8
70.2440,1573.9
70.2950,1544.1
70.3460,1592.9
70.3970,1576.3
70.4480,1568.5
70.4990,1610.8
70.5500,1573.7
70.6010,1593.9
70.6520,1623.1
70.7030,1635.5
70.7540,1565.5
70.8050,1624.5
70.8560,1574.2
70.9070,1610.1
70.9580,1633.5
71.0090,1567.4
71.0600,1608.5
71.1110,1601.8
71.1620,1617.4
71.2130,1634.3
71.2640,1641.8
71.3150,1513.2
71.3660,1602.2
71.4170,1623.5
71.4680,1594.6
71.5190,1640.4
71.5700,1598.2
71.6210,1589.4
71.6720,1637.6
71.7230,1650.7
71.7740,1640.6
71.8250,1658.0
71.8760,1635.4
71.9270,1599.0
71.9780,1651.8
72.0290,1610.2
72.0800,1676.5
72.1310,1643.3
72.1820,1610.2
72.2330,1594.4
72.2840,1609.2
72.3350,1588.2
72.3860,1649.4
72.4370,1616.1
72.4880,1659.4
72.5390,1646.6
72.5900,1677.8
72.6410,1613.6
72.6920,1626.5
72.7430,1603.2
72.7940,1653.3
72.8450,1632.7
72.8960,1640.5
72.9470,1662.8
72.9980,1601.0
73.0490,1643.1
73.1000,1669.8
73.1510,1610.0
73.2020,1697.7
73.2530,1645.8
73.3040,1630.8
73.3550,1702.5
73.4060,1695.8
73.4570,1641.6
73.5080,1661.4
73.5590,1739.1
73.6100,1840.8
73.6610,1907.8
73.7120,2026.9
73.7630,2022.4
73.8140,2173.9
73.8650,2356.9
73.9160,2828.4
73.9670,4702.0
74.0180,12956.5
74.0690,30650.4
74.1200,18199.5
74.1710,7092.6
74.2220,3806.4
74.2730,2752.5
74.3240,2400.4
74.3750,2180.3
74.4260,2025.6
74.4770,1927.7
74.5280,1839.5
74.5790,1661.5
74.6300,1728.6
74.6810,1685.2
74.7320,1692.4
74.7830,1701.2
74.8340,1684.4
74.8850,1734.9
74.9360,1653.3
74.9870,1635.4
75.0380,1649.8
75.0890,1700.4
75.1400,1658.2
75.1910,1643.1
75.2420,1616.8
75.2930,1627.1
75.3440,1636.1
75.3950,1651.8
75.4460,1620.4
75.4970,1612.1
75.5480,1653.9
75.5990,1666.2
75.6500,1654.5
75.7010,1648.4
75.7520,1678.5
75.8030,1652.3
75.8540,1607.9
75.9050,1658.8
75.9560,1703.4
76.0070,1664.6
76.0580,1659.6
76.1090,1611.6
76.1600,1681.2
76.2110,1662.4
76.2620,1596.6
76.3130,1639.5
76.3640,1646.1
76.4150,1609.7
76.4660,1642.8
76.5170,1587.0
76.5680,1619.1
76.6190,1604.3
76.6700,1643.4
76.7210,1617.4
76.7720,1621.0
76.8230,1625.6
76.8740,1612.9
76.9250,1616.7
76.9760,1588.8
77.0270,1606.4
77.0780,1662.5
77.1290,1612.3
77.1800,1598.6
77.2310,1645.4
77.2820,1633.4
77.3330,1634.5
77.3840,1618.1
77.4350,1658.9
77.4860,1601.9
77.5370,1607.5
77.5880,1667.1
77.6390,1641.5
77.6900,1616.2
77.7410,1585.7
77.7920,1656.9
77.8430,1649.2
77.8940,1572.9
77.9450,1658.5
77.9960,1663.9
78.0470,1634.8
78.0980,1591.9
78.1490,1596.4
78.2000,1632.7
78.2510,1653.4
78.3020,1607.8
78.3530,1627.4
78.4040,1641.4
78.4550,1606.7
78.5060,1594.7
78.5570,1611.6
78.6080,1637.7
78.6590,1623.1
78.7100,1639.0
78.7610,1649.1
78.8120,1597.2
78.8630,1602.9
78.9140,1624.3
78.9650,1651.2
79.0160,1595.1
79.0670,1646.6
79.1180,1526.5
79.1690,1631.2
79.2200,1621.9
79.2710,1664.4
79.3220,1602.2
79.3730,1610.1
79.4240,1672.4
79.4750,1640.6
79.5260,1608.8
79.5770,1624.5
79.6280,1628.2
79.6790,1655.0
79.7300,1645.4
79.7810,1634.1
79.8320,1650.5
79.8830,1627.5
79.9340,1589.4
79.9680,1529.4