File: Result/Raw data/XRD_550C_raw/SAMPLE_6_COPPER_45mins_550C.XRDML striped k alpha 2.XRDML
<?xml version="1.0" encoding="UTF-8"?>
<xrdMeasurements xmlns="http://www.xrdml.com/XRDMeasurement/1.5" xmlns:xsi="http://www.w3.org/2001/XMLSchema-instance" xsi:schemaLocation="http://www.xrdml.com/XRDMeasurement/1.5 http://www.xrdml.com/XRDMeasurement/1.5/XRDMeasurement.xsd" status="Completed">
	<comment>
		<entry>Configuration=Flat Sample Stage, Owner=User-1, Creation date=3/25/2015 2:10:01 PM</entry>
		<entry>Goniometer=PW3050/60 (Theta/Theta); Minimum step size 2Theta:0.001; Minimum step size Omega:0.001</entry>
		<entry>Sample stage=PW3071/xx Bracket</entry>
		<entry>Diffractometer system=XPERT-PRO</entry>
		<entry>Measurement program=C:\PANalytical\Data Collector\Programs\Flat sample Scan.xrdmp, Identifier={A9F6D0C0-202E-4C59-A4F1-A5BA86123012}</entry>
		<entry/>
	</comment>
	<xrdMeasurement measurementType="Scan" status="Completed" sampleMode="Reflection">
		<usedWavelength intended="K-Alpha 1">
			<kAlpha1 unit="Angstrom">1.540598</kAlpha1>
			<kAlpha2 unit="Angstrom">1.544426</kAlpha2>
			<kBeta unit="Angstrom">1.392250</kBeta>
			<ratioKAlpha2KAlpha1>0.000000</ratioKAlpha2KAlpha1>
		</usedWavelength>
		<incidentBeamPath>
			<radius unit="mm">240.000</radius>
			<xRayTube>
				<tension unit="kV">40</tension>
				<current unit="mA">30</current>
				<anodeMaterial>Cu</anodeMaterial>
			</xRayTube>
			<divergenceSlit xsi:type="fixedDivergenceSlitType">
				<angle unit="deg">0.500</angle>
			</divergenceSlit>
		</incidentBeamPath>
		<diffractedBeamPath>
			<radius unit="mm">240.000</radius>
			<receivingSlit>
				<height unit="mm">0.100</height>
			</receivingSlit>
		</diffractedBeamPath>
		<scan appendNumber="0" mode="Continuous" scanAxis="Gonio" status="Completed">
			<header>
				<startTimeStamp>2020-02-27T18:08:51</startTimeStamp>
				<author>
					<name>user-1</name>
				</author>
				<source>
					<applicationSoftware version="4.1.0">HighScore</applicationSoftware>
				</source>
			</header>
			<dataPoints>
				<positions axis="2Theta" unit="deg">
					<startPosition>20.008</startPosition>
					<endPosition>79.984</endPosition>
				</positions>
				<commonCountingTime unit="seconds">34.925</commonCountingTime>
				<intensities unit="counts">651 706 687 695 670 668 679 685 680 663 681 652 656 638 694 676 665 686 670 676 676 645 673 690 698 685 696 689 651 641 658 664 670 664 664 656 681 690 698 671 677 645 695 689 658 679 664 666 688 693 687 668 704 674 763 701 688 672 685 671 751 687 676 667 668 680 679 632 686 673 657 689 636 663 691 688 664 696 695 684 686 685 658 675 683 676 676 663 672 655 645 729 740 675 687 688 677 701 702 692 697 703 683 676 698 673 662 664 665 675 633 682 692 681 668 686 668 734 675 669 645 691 683 694 657 671 691 665 698 678 696 707 696 658 645 694 695 654 653 654 682 678 674 691 731 696 668 660 679 703 678 693 708 677 677 679 679 693 698 703 704 727 688 638 693 712 667 664 660 696 654 703 666 703 669 662 702 686 700 668 696 671 696 715 697 674 709 754 709 708 699 678 719 722 712 721 705 683 680 693 707 671 688 701 692 677 691 691 690 676 674 683 681 659 681 696 665 687 698 697 699 634 694 706 727 693 723 670 692 707 690 711 696 714 684 704 724 690 696 714 685 693 709 718 687 695 691 690 689 670 690 677 695 698 703 733 693 704 702 700 736 732 686 704 708 684 700 728 722 667 705 732 694 706 724 696 709 720 720 740 703 685 727 739 714 703 711 717 728 680 698 711 683 707 693 731 736 730 716 702 721 675 711 694 701 724 716 705 693 698 685 685 704 726 715 725 735 723 735 722 716 733 735 715 700 730 740 711 702 710 715 710 708 713 697 715 717 759 699 761 766 667 737 717 740 713 745 719 761 775 725 718 716 728 712 712 732 745 717 763 733 738 735 736 727 712 714 701 743 725 714 703 714 722 718 746 743 725 720 724 718 718 734 722 733 745 720 707 700 728 713 709 740 732 761 765 733 703 711 734 767 744 750 748 749 722 728 724 716 729 706 714 763 722 765 733 739 769 771 752 725 756 738 733 736 745 753 762 760 768 737 732 802 795 777 773 725 735 733 750 752 723 746 758 734 712 727 726 770 765 759 776 737 740 706 777 779 743 726 776 745 763 753 757 758 744 771 735 745 770 750 760 747 753 752 746 759 744 760 730 765 774 746 755 760 734 737 767 752 784 783 768 763 749 759 743 762 780 753 747 762 748 767 764 756 770 727 747 771 801 794 769 727 779 799 761 762 782 766 782 764 748 733 685 726 785 760 763 748 758 767 776 766 795 772 776 786 792 811 792 780 769 761 772 790 816 808 779 774 783 811 795 750 769 793 797 816 778 774 783 772 766 748 754 754 742 788 801 751 745 767 757 771 752 760 763 794 809 730 734 752 797 754 800 765 802 813 763 780 772 746 762 765 761 758 769 795 786 768 754 768 799 786 773 791 784 769 786 775 763 778 769 740 754 788 757 780 799 816 801 778 781 776 770 797 787 802 814 788 859 773 769 779 757 802 774 782 810 779 751 802 755 785 809 843 760 765 771 743 786 796 842 787 733 768 799 806 782 790 803 796 794 783 771 778 781 800 841 794 780 785 773 762 763 757 773 766 759 781 796 799 817 791 765 751 772 828 796 775 759 776 799 806 791 808 777 759 807 818 787 775 802 798 775 782 783 757 755 806 798 751 754 811 821 811 793 768 768 801 812 800 789 772 764 788 817 781 796 793 755 793 815 798 792 816 797 784 818 812 793 766 804 770 825 778 778 811 812 832 801 806 793 799 833 821 801 782 845 811 803 812 821 805 779 781 794 825 786 798 839 820 810 799 825 830 825 819 818 813 814 802 804 809 811 816 810 820 820 832 804 790 808 794 796 795 813 840 833 835 813 808 779 770 828 818 813 818 790 825 803 787 800 822 852 841 802 788 819 819 828 819 810 797 793 794 777 818 801 795 808 846 817 841 836 795 845 827 785 795 813 786 793 796 797 787 774 796 826 831 820 821 789 799 820 890 839 817 802 808 787 774 793 821 801 779 809 797 791 822 893 833 809 823 799 774 821 814 804 828 799 795 802 790 802 813 827 829 810 835 843 811 810 812 827 821 825 831 833 810 815 814 806 801 839 861 851 861 834 826 835 849 847 838 820 831 861 790 810 828 846 861 869 822 820 843 827 847 821 860 811 812 868 820 827 815 850 820 792 807 836 831 848 831 830 823 832 823 821 820 809 807 834 832 822 832 831 840 831 824 832 822 833 819 800 815 834 857 852 832 807 818 862 846 859 860 859 856 822 868 857 845 821 808 832 848 871 828 807 847 802 801 862 867 868 834 844 827 842 826 842 839 840 876 855 861 874 861 845 820 837 822 821 854 825 800 820 818 841 870 851 831 841 846 846 847 846 847 845 844 829 835 840 862 873 818 832 865 833 819 840 834 815 855 825 881 862 824 822 838 844 816 823 817 827 861 868 857 855 841 852 818 838 837 854 849 828 847 833 837 845 861 855 842 856 892 880 832 857 837 830 846 872 870 848 824 820 833 866 849 848 878 882 898 844 834 838 867 896 877 954 829 825 847 819 840 855 838 893 858 829 870 863 874 865 826 866 833 838 838 828 835 852 872 878 843 825 835 822 842 854 861 881 871 873 882 860 874 863 836 838 852 852 845 853 868 837 843 890 867 838 859 830 864 834 851 851 888 844 874 918 856 856 858 829 900 844 847 869 886 914 869 828 890 881 856 879 886 883 843 840 869 863 868 850 869 879 849 843 842 847 849 881 892 871 868 861 868 888 893 854 879 900 881 877 889 883 852 849 823 850 855 908 877 870 886 886 901 826 896 865 841 866 894 886 890 877 871 905 857 850 865 832 906 946 917 903 898 876 861 871 894 891 879 886 899 878 867 850 846 859 865 859 894 892 856 855 874 906 884 903 888 884 877 881 877 854 849 845 866 927 906 843 887 909 875 878 907 846 955 899 861 895 862 916 919 933 910 942 898 898 896 907 883 894 930 950 911 887 919 937 921 903 894 891 888 885 903 907 936 931 928 904 887 883 920 913 922 871 899 928 935 906 915 925 907 949 959 920 895 915 913 938 884 918 905 903 890 973 931 925 943 939 905 927 964 916 906 940 966 950 1054 1001 1087 1137 1163 1214 1207 1221 1284 1316 1429 1605 1932 2496 3501 5457 9419 14248 16182 13660 9858 6736 4514 3112 2431 1795 1383 1274 1303 1113 1116 1029 1047 1119 1051 996 1029 977 1021 971 1002 1038 959 959 987 1037 957 953 953 926 965 919 927 942 939 935 896 934 944 938 938 937 947 959 969 955 930 919 923 939 947 942 925 929 932 916 927 902 927 920 931 954 922 912 924 923 932 896 917 961 909 928 943 968 943 914 904 863 930 924 1014 907 930 904 931 924 955 933 936 908 944 925 923 941 960 938 938 936 903 904 914 936 936 894 921 953 945 935 941 940 961 957 933 957 983 960 963 976 962 920 933 936 939 931 933 937 958 930 887 927 937 938 935 944 912 941 891 892 916 931 931 947 925 886 884 953 930 919 936 959 956 935 930 969 916 917 925 904 916 948 986 943 923 944 928 927 918 925 909 928 924 946 938 951 947 960 941 906 934 943 913 929 925 928 924 933 876 923 955 926 904 942 907 918 939 926 957 900 966 927 912 958 951 919 942 894 938 948 944 965 944 928 890 961 933 936 930 923 920 903 927 935 931 925 918 938 961 941 911 908 945 967 963 927 920 944 947 929 927 933 991 918 906 944 967 975 905 956 922 956 950 891 961 928 894 932 945 948 956 935 923 940 944 947 923 923 944 908 917 927 918 932 896 920 973 954 905 895 906 914 936 950 943 946 949 963 961 941 961 957 938 942 957 926 922 966 921 926 921 917 931 913 957 934 921 956 934 907 977 951 1019 959 968 1003 998 962 966 1013 983 999 975 954 962 967 971 965 987 1008 1004 1007 1035 980 992 1009 989 993 1007 1017 1035 1017 998 1007 1018 1003 984 1021 1039 1040 1011 1002 988 1001 1009 966 972 988 975 938 1007 993 1007 993 1029 1084 1026 987 1032 1001 988 987 982 980 1050 1039 1002 1020 1014 1027 1019 1024 1014 1009 1041 1030 1042 1015 1018 1050 1069 1062 1069 1072 1074 1068 1082 1099 1141 1181 1236 1357 1489 1609 1674 1776 1841 1886 1895 1952 2077 2529 3281 4453 6641 10698 17688 29551 40878 42489 32439 21285 13126 7967 5137 3461 2919 2811 2487 1976 1714 1687 1601 1606 1418 1150 1052 1099 1194 1028 1035 1042 1081 1177 1190 1101 1089 1072 1060 1059 1081 1054 1068 1080 1054 1051 1026 1003 1022 1044 1048 1037 1003 1030 1041 1020 1044 1016 1001 1020 990 994 1001 967 1001 992 1037 989 1030 1034 1027 981 1027 974 1003 1047 1002 972 977 989 963 967 991 965 934 950 989 1014 1019 991 1018 992 1008 962 981 971 968 956 982 1021 1013 988 991 996 1000 995 983 991 1005 1018 981 959 982 1008 997 973 973 992 1009 1013 991 960 960 997 980 967 932 946 996 986 970 955 993 991 976 934 962 963 983 967 990 996 945 1009 1004 965 985 977 1013 998 987 992 965 987 970 939 960 963 955 962 975 972 1002 997 962 966 957 970 991 974 949 921 954 974 942 905 931 966 960 1001 993 941 957 970 983 907 964 977 978 957 953 990 984 967 978 935 961 970 948 928 965 984 950 987 998 969 951 968 990 988 959 947 954 947 988 1015 974 955 968 991 958 944 1003 1003 990 974 980 950 956 977 961 930 961 972 972 969 1002 956 1003 978 962 965 985 966 939 969 967 940 900 921 982 1002 968 956 912 993 963 972 986 938 960 965 1011 980 947 966 988 988 992 1003 991 967 961 953 967 975 986 985 970 988 969 954 974 962 991 978 939 968 976 983 922 960 953 935 982 964 977 963 1000 992 951 950 943 927 918 973 940 987 983 935 980 952 968 979 945 952 943 976 983 961 985 966 973 1026 991 954 973 983 946 922 968 967 941 953 962 961 954 955 935 951 956 954 976 1006 991 970 987 973 974 1015 997 940 937 947 955 950 957 982 999 934 985 954 981 1015 1011 942 1007 918 991 1032 966 970 983 956 965 969 954 997 965 945 934 939 958 960 974 974 956 950 948 971 986 973 947 954 956 990 971 962 998 970 949 959 974 968 974 988 1016 989 981 970 961 988 939 929 932 954 910 980 945 972 945 971 971 964 980 952 941 968 987 972 980 992 933 950 940 961 959 980 989 1006 990 936 949 949 952 972 975 958 952 969 972 958 1003 1011 979 978 968 978 991 970 991 962 963 976 991 990 941 960 966 1006 979 994 958 951 983 995 939 960 942 954 983 937 997 965 947 974 990 1010 999 971 951 966 966 981 941 961 957 954 1001 967 951 977 934 946 945 972 987 962 982 977 953 951 984 988 978 951 960 994 988 955 948 925 950 974 1040 1072 925 944 943 936 952 962 1004 939 957 921 949 1062 952 1005 962 933 952 975 987 972 1003 960 974 994 950 953 955 931 952 983 951 962 962 967 940 958 982 988 1007 1012 981 962 971 985 980 971 962 991 976 972 987 968 940 919 959 980 977 946 982 924 953 963 938 979 953 957 974 1031 942 976 999 933 1005 950 958 1005 931 974 974 943 956 939 973 952 970 937 929 966 976 956 987 997 955 965 981 956 986 1001 982 986 1012 987 973 991 998 961 989 995 946 919 954 1029 975 966 967 970 950 1013 973 974 1009 965 978 985 978 973 987 981 989 981 963 921 957 979 971 1003 973 973 998 981 985 988 950 982 956 967 959 949 981 972 938 961 978 1000 1030 1001 985 950 945 954 956 957 967 943 957 964 945 982 973 1009 986 973 996 955 1000 960 1013 918 954 967 978 958 974 981 976 966 933 971 1013 948 948 938 994 950 983 951 953 968 964 953 946 993 952 960 954 1020 1012 1019 1027 1005 999 980 954 968 947 955 956 962 972 969 996 1003 1002 1005 979 994 989 1002 967 934 966 960 903 943 952 946 930 974 998 997 1018 997 960 961 967 973 994 981 1012 959 1000 1023 971 994 978 954 955 1003 1011 964 961 989 994 967 963 994 1006 967 981 1000 996 1000 1004 999 995 984 998 1019 1001 994 1002 990 986 962 938 959 960 948 966 993 988 962 957 990 975 935 1000 980 1002 946 1013 980 987 1012 982 996 1012 978 992 969 1008 973 949 980 928 964 969 969 954 954 980 980 1003 981 989 1009 993 991 964 961 980 982 975 998 996 972 968 955 960 1011 979 985 978 1022 998 959 970 968 980 996 985 973 977 956 968 974 979 954 992 1041 991 958 952 990 988 995 1000 998 951 965 971 981 974 1001 980 1015 987 984 1026 1017 988 1001 975 963 965 990 993 964 962 995 1022 1002 988 999 987 986 987 1020 1003 997 991 993 968 999 1022 1013 993 1005 1017 984 992 997 1007 1011 952 939 948 989 979 957 984 1018 991 1002 981 979 937 962 996 966 999 974 1003 978 1001 992 976 998 1020 1033 994 972 1001 987 970 954 954 974 979 981 967 981 988 995 1014 1047 1020 1016 1006 1035 1014 982 973 967 990 990 997 979 1049 998 1010 1009 1013 973 1018 966 991 1005 984 945 991 982 957 971 973 992 1024 975 1002 1024 978 968 1028 997 992 1012 1043 1019 990 995 998 1005 1013 999 993 1004 982 971 1001 971 978 991 998 1008 1014 1011 1020 978 985 977 929 953 979 1017 992 1007 1000 961 1013 1015 1122 1008 1011 1005 1042 989 1009 1010 1019 1008 998 986 992 1015 1014 1023 1016 998 1043 985 979 1009 1019 998 991 958 968 1006 995 992 992 984 976 983 1000 997 991 1021 1015 987 1000 986 971 1018 965 960 969 994 982 992 969 985 976 1010 988 1004 996 962 974 1015 1045 1008 1014 1002 1000 1046 992 960 1002 1027 1012 1017 988 1002 988 1000 1002 1027 1005 999 990 1006 1002 993 1005 1007 1016 1023 1027 1005 986 972 995 996 1010 1015 1030 1024 1034 989 1013 1037 1021 1015 992 1004 997 1028 1037 993 1030 967 1003 1035 1050 1027 1038 1024 1001 980 1064 1037 977 1057 1014 1004 1023 980 1011 998 1040 1009 968 1023 1009 1018 1033 1000 1015 1040 1029 1010 1000 1020 1009 1010 1014 991 1006 996 978 1012 1023 1011 1002 993 1026 1015 1017 1020 1011 1012 996 1026 1004 995 998 1030 1032 1007 1034 1013 1002 1038 1037 987 1033 1044 1030 1055 1017 1014 1017 1056 1024 1010 1016 1000 1017 1012 1006 1011 980 998 1029 1050 1019 1043 1035 1037 1055 1058 1054 1048 1025 1007 1041 1041 1026 1018 1021 1042 1062 1032 1038 1004 997 1039 1062 1084 1064 1009 1048 1054 1025 1044 1028 977 995 1054 1032 1019 1023 1001 1065 1025 1068 1045 1023 1052 1015 1064 1069 1042 1045 1010 1062 1039 1056 1045 1063 1056 1041 1040 1028 1017 1044 1040 1042 1060 1049 1067 1065 1032 1046 1041 1040 1021 1047 1058 1032 1032 1072 1067 1034 1021 1063 1060 1050 1040 1031 1050 1008 1015 1028 1075 1031 990 1043 1073 1011 1064 1028 1053 1014 1110 1094 1084 1036 1090 1055 1039 1051 1047 1077 1066 1049 1092 1085 1031 1038 1075 1089 1093 1093 1092 1078 1086 1158 1235 1245 1233 1268 1330 1307 1230 1233 1257 1228 1296 1323 1302 1348 1435 1460 1576 1732 2033 2540 3394 5086 8267 13367 18333 19148 15286 10581 7056 4736 3333 2528 2038 1715 1502 1451 1379 1222 1036 1468 1333 1275 1280 1166 1134 1252 1196 1255 1172 1157 1243 1202 1073 1093 1129 1132 1123 1122 1110 1116 1112 1083 1080 1103 1125 1080 1068 1104 1100 1075 1061 1082 1122 1082 1082 1072 1046 1066 1041 1112 1055 1050 1041 1034 1068 1085 1078 1058 1043 1062 1069 1105 1045 1069 1039 1069 1066 1092 1076 1055 1050 1071 1072 1022 1035 1041 1039 1044 1089 1068 1061 1076 1047 1052 1053 1058 1072 1074 1050 1054 1072 1049 1052 1067 1075 1070 1027 1009 1055 1058 1053 1037 1096 1087 1082 1049 1059 1037 1024 1054 1060 1036 1063 1062 1041 1060 1015 1029 1016 1107 1084 1092 1054 1070 1048 1068 1059 1105 1072 1060 1073 1071 1052 1048 1075 1059 1065 1055 1033 1048 1050 1057 1054 1054 1038 1070 1109 1100 1045 1046 1085 1032 1043 1060 1052 1017 1057 1048 1010 1024 1060 1065 1088 1047 1075 1049 1094 1072 1029 1001 1083 1072 1066 1027 1076 1094 1025 1058 1089 1086 1021 1031 1053 1067 1023 1070 1022 1050 1058 1065 1046 1064 1070 1038 1030 1031 1063 1049 1036 1010 1030 1057 1036 1039 1052 1026 1060 1084 1044 1041 1053 1048 1047 1059 1064 1052 1024 1053 1058 1042 1071 1046 1075 1040 1033 1052 1020 1043 1056 1064 1085 1075 1076 985 1060 1031 1045 1063 1084 1085 1070 1057 1050 1029 1061 1036 1060 1046 1024 1055 1081 1058 1046 1027 1047 1061 1068 1075 1046 1031 1037 1024 1022 1041 1074 1089 1077 1057 1052 1034 1034 1058 1094 1090 1035 1030 1054 1074 1036 1037 1062 1030 1040 1048 1084 1070 1125 1059 1043 1072 1015 1040 1049 1078 1041 1065 1048 1059 1063 1054 1060 1053 1091 1071 1059 1058 1056 1040 1053 1069 1077 1048 1061 1055 1046 1072 1078 1062 1032 1054 1063 1051 1044 1059 1046 1020 1040 1038 1057 1082 1038 1067 1064 1053 1039 1070 1058 1048 1040 1056 1058 1061 1058 1071 1063 1058</intensities>
			</dataPoints>
			<nonAmbientPoints type="Temperature" unit="K">
				<measurementTimes unit="seconds" deltaTime="1">0</measurementTimes>
				<nonAmbientValues>298.000</nonAmbientValues>
			</nonAmbientPoints>
		</scan>
	</xrdMeasurement>
</xrdMeasurements>