File: Result/Raw data/XRD_550C_raw/SAMPLE_5_COPPER_1HOUR_550C.XRDML striped k alpha 2.XRDML
<?xml version="1.0" encoding="UTF-8"?>
<xrdMeasurements xmlns="http://www.xrdml.com/XRDMeasurement/1.5" xmlns:xsi="http://www.w3.org/2001/XMLSchema-instance" xsi:schemaLocation="http://www.xrdml.com/XRDMeasurement/1.5 http://www.xrdml.com/XRDMeasurement/1.5/XRDMeasurement.xsd" status="Completed">
	<comment>
		<entry>Configuration=Flat Sample Stage, Owner=User-1, Creation date=3/25/2015 2:10:01 PM</entry>
		<entry>Goniometer=PW3050/60 (Theta/Theta); Minimum step size 2Theta:0.001; Minimum step size Omega:0.001</entry>
		<entry>Sample stage=PW3071/xx Bracket</entry>
		<entry>Diffractometer system=XPERT-PRO</entry>
		<entry>Measurement program=C:\PANalytical\Data Collector\Programs\Flat sample Scan.xrdmp, Identifier={3634D59B-DE38-49D5-A63D-E2FEC0D6EAF3}</entry>
		<entry/>
	</comment>
	<xrdMeasurement measurementType="Scan" status="Completed" sampleMode="Reflection">
		<usedWavelength intended="K-Alpha 1">
			<kAlpha1 unit="Angstrom">1.540598</kAlpha1>
			<kAlpha2 unit="Angstrom">1.544426</kAlpha2>
			<kBeta unit="Angstrom">1.392250</kBeta>
			<ratioKAlpha2KAlpha1>0.000000</ratioKAlpha2KAlpha1>
		</usedWavelength>
		<incidentBeamPath>
			<radius unit="mm">240.000</radius>
			<xRayTube>
				<tension unit="kV">40</tension>
				<current unit="mA">30</current>
				<anodeMaterial>Cu</anodeMaterial>
			</xRayTube>
			<divergenceSlit xsi:type="fixedDivergenceSlitType">
				<angle unit="deg">0.500</angle>
			</divergenceSlit>
		</incidentBeamPath>
		<diffractedBeamPath>
			<radius unit="mm">240.000</radius>
			<receivingSlit>
				<height unit="mm">0.100</height>
			</receivingSlit>
		</diffractedBeamPath>
		<scan appendNumber="0" mode="Continuous" scanAxis="Gonio" status="Completed">
			<header>
				<startTimeStamp>2020-02-27T18:08:00</startTimeStamp>
				<author>
					<name>user-1</name>
				</author>
				<source>
					<applicationSoftware version="4.1.0">HighScore</applicationSoftware>
				</source>
			</header>
			<dataPoints>
				<positions axis="2Theta" unit="deg">
					<startPosition>5.008</startPosition>
					<endPosition>79.978</endPosition>
				</positions>
				<commonCountingTime unit="seconds">34.925</commonCountingTime>
				<intensities unit="counts">1664 1641 1701 1591 1604 1619 1661 1637 1589 1618 1622 1586 1535 1594 1589 1566 1555 1547 1551 1528 1527 1570 1568 1561 1522 1504 1512 1498 1526 1542 1489 1465 1476 1492 1479 1502 1503 1465 1459 1493 1476 1450 1450 1444 1468 1431 1439 1473 1460 1398 1427 1418 1412 1423 1399 1428 1422 1505 1368 1409 1435 1394 1352 1430 1411 1382 1374 1402 1410 1345 1369 1369 1378 1351 1380 1324 1393 1354 1350 1388 1356 1336 1336 1327 1330 1321 1341 1310 1288 1322 1324 1296 1285 1314 1295 1302 1290 1288 1292 1302 1330 1261 1222 1247 1273 1249 1280 1259 1252 1261 1242 1277 1241 1232 1252 1175 1216 1244 1250 1203 1188 1255 1196 1218 1187 1160 1136 1200 1193 1210 1217 1241 1169 1158 1185 1168 1180 1185 1201 1175 1170 1162 1143 1156 1188 1163 1138 1147 1154 1170 1145 1147 1107 1097 1091 1075 1106 1117 1128 1139 1139 1139 1115 1156 1135 1111 1084 1142 1048 1112 1072 1082 1072 1052 1082 1110 1065 1138 1060 1093 1069 1085 1110 1064 1068 1073 1080 1060 1047 1040 1060 1078 1076 1058 1047 1032 1059 1064 1052 1069 1084 1070 1016 1022 1046 1057 1035 1033 1067 1035 1028 1044 1040 1035 1064 1001 1049 1042 987 998 991 1050 1036 986 1014 1009 1040 1026 988 1059 1055 1036 995 995 1011 979 985 994 1027 973 991 1018 997 1003 973 956 981 994 989 965 968 1006 983 964 972 975 971 953 945 984 1006 979 982 984 921 950 953 947 973 967 932 939 984 967 950 980 959 956 962 966 966 980 923 981 926 937 961 942 899 979 957 981 960 964 965 942 998 950 937 973 935 937 963 976 957 937 946 932 948 955 919 950 972 934 903 945 933 925 968 951 926 914 935 938 932 960 958 898 927 948 932 940 955 912 911 938 936 884 917 917 944 925 934 911 921 938 900 913 926 924 969 955 917 931 925 914 917 920 989 960 938 944 920 905 936 904 914 932 927 923 918 909 930 920 917 950 931 929 925 933 938 932 952 939 947 956 941 917 917 894 894 921 901 870 899 886 890 897 918 912 928 934 906 954 855 893 918 851 898 913 886 917 937 945 927 878 924 894 907 927 882 902 929 929 909 899 913 921 895 901 915 906 923 917 929 925 912 884 880 881 892 918 931 914 885 926 877 893 889 882 895 897 871 914 914 906 871 922 913 916 909 886 892 909 888 924 906 903 884 907 922 909 906 916 898 919 917 902 896 910 905 903 887 871 867 864 888 894 910 901 876 894 895 905 893 903 903 892 886 871 874 913 904 919 943 923 907 890 892 886 874 900 920 923 888 899 875 873 901 894 906 875 872 888 926 928 905 891 888 909 880 947 901 907 894 862 894 906 1004 903 902 901 919 914 898 905 911 882 886 916 908 903 881 873 899 893 905 907 898 923 926 921 924 893 888 887 941 929 919 901 881 888 905 885 907 933 901 900 940 941 928 892 933 911 888 899 894 888 916 907 884 907 867 915 950 942 922 920 918 909 933 897 888 916 898 896 907 897 893 893 896 885 882 910 936 919 849 869 894 902 926 864 904 873 883 901 925 904 914 902 935 896 921 931 919 942 908 905 933 965 881 931 906 919 897 917 933 931 922 898 870 914 916 905 919 905 895 932 975 931 915 920 929 913 920 924 910 915 951 931 922 952 961 935 903 884 915 900 866 910 942 931 910 880 921 910 891 925 906 889 910 958 945 919 929 929 905 890 925 923 921 939 872 919 940 930 919 949 936 942 918 906 928 928 933 933 938 947 930 929 949 963 953 943 949 939 924 913 923 939 915 902 937 970 956 933 943 932 909 939 940 933 958 951 953 944 917 977 925 913 911 918 945 951 952 916 906 944 963 956 949 907 950 957 960 951 927 936 924 934 964 945 928 966 966 947 958 971 953 957 969 953 936 950 969 979 954 969 956 955 979 976 968 975 978 966 973 962 933 970 933 972 936 965 1007 965 954 986 962 939 928 972 992 1004 971 944 990 1009 935 958 958 960 954 961 955 963 970 963 951 950 985 951 970 1041 997 961 958 986 967 960 975 981 963 956 983 951 944 988 994 958 955 962 990 973 965 988 970 969 960 1001 992 1035 982 969 951 966 942 963 990 927 967 933 1009 990 1003 989 1001 962 968 1017 988 975 972 994 988 969 971 949 997 1006 998 997 1011 1002 998 981 961 994 951 969 1036 1042 1046 1017 984 1008 970 996 989 1006 1005 977 974 990 1017 1010 991 994 991 1000 1007 1020 1015 992 988 1023 1008 970 988 972 1018 1016 1035 982 980 1040 1004 986 1009 1003 1023 1040 999 992 1002 1021 977 989 994 997 987 998 1004 1001 1006 1031 1068 1036 1017 1015 998 996 1012 996 1029 1018 1032 1021 1036 1045 1019 1009 1023 1043 1024 1020 1009 1018 1027 1000 1030 1035 1054 1040 969 1007 1036 1005 1070 1031 1014 1014 993 1027 1020 1042 1026 1046 1083 1034 1054 1047 1019 1032 1045 1020 1014 1015 1002 1018 1025 1020 1018 1020 1018 1024 1048 1047 1019 1041 1057 1038 1049 1026 1050 1045 1010 1020 1047 1039 1055 1058 1026 1032 1005 1055 1037 1065 1092 1006 1050 1051 1000 1073 1052 1074 1076 1106 1036 1084 1039 1056 1039 1027 1065 1043 1081 1077 1063 1076 1048 1058 1067 1076 1082 1080 1092 1097 1058 1029 1073 1096 1080 1064 1067 1064 1056 1062 1083 1083 1071 1053 1050 1076 1092 1059 1079 1038 990 1010 1043 1088 1077 1062 1070 1108 1103 1110 1064 1098 1103 1084 1042 1051 1120 1038 1047 1085 1077 1064 1061 1069 1080 1007 1048 1111 1112 1098 1070 1073 1066 1063 1079 1097 1080 1080 1083 1072 1105 1112 1098 1078 1057 1053 1053 1100 1106 1105 1144 1083 1110 1123 1093 1084 1114 1124 1109 1042 1057 1087 1060 1091 1153 1074 1070 1134 1096 1128 1165 1110 1131 1075 1107 1143 1065 1061 1101 1061 1068 1089 1092 1122 1115 1127 1120 1111 1113 1104 1089 1070 1085 1088 1088 1108 1108 1128 1143 1122 1094 1119 1133 1097 1096 1118 1122 1135 1112 1132 1102 1112 1109 1153 1151 1099 1115 1098 1145 1118 1100 1107 1086 1125 1149 1089 1130 1182 1108 1102 1111 1130 1128 1140 1152 1118 1078 1103 1081 1109 1136 1144 1174 1135 1131 1119 1138 1137 1161 1144 1144 1130 1108 1143 1150 1151 1146 1127 1139 1140 1118 1127 1147 1165 1161 1154 1143 1200 1196 1130 1116 1128 1139 1157 1139 1161 1114 1127 1132 1156 1192 1131 1213 1142 1119 1112 1142 1168 1138 1128 1139 1222 1165 1186 1182 1145 1129 1130 1132 1168 1145 1168 1151 1165 1156 1161 1174 1203 1174 1178 1123 1152 1211 1208 1175 1170 1198 1174 1185 1175 1149 1162 1180 1134 1198 1156 1170 1185 1168 1165 1158 1161 1209 1202 1160 1180 1203 1196 1187 1195 1162 1178 1170 1149 1207 1179 1200 1201 1164 1191 1199 1200 1158 1174 1163 1191 1164 1195 1210 1189 1210 1157 1215 1193 1168 1183 1196 1184 1169 1217 1219 1219 1175 1157 1206 1203 1169 1184 1210 1203 1202 1195 1213 1230 1173 1193 1186 1199 1176 1193 1188 1178 1183 1162 1148 1192 1254 1229 1233 1206 1188 1182 1222 1194 1340 1218 1204 1192 1191 1245 1240 1213 1185 1221 1213 1204 1216 1197 1209 1241 1258 1229 1177 1193 1229 1222 1189 1183 1198 1214 1210 1217 1193 1179 1202 1227 1226 1239 1242 1255 1221 1253 1221 1203 1218 1214 1228 1208 1222 1210 1239 1226 1183 1242 1229 1257 1205 1214 1227 1190 1222 1242 1319 1235 1255 1260 1172 1237 1249 1226 1279 1233 1222 1230 1241 1290 1268 1205 1199 1223 1231 1249 1291 1273 1241 1237 1262 1250 1232 1253 1221 1219 1256 1261 1226 1228 1239 1223 1247 1235 1238 1242 1255 1289 1244 1241 1212 1235 1220 1223 1266 1237 1294 1286 1209 1271 1263 1285 1232 1206 1227 1206 1279 1249 1236 1218 1234 1275 1211 1225 1247 1255 1279 1262 1254 1283 1257 1235 1213 1217 1228 1268 1261 1243 1251 1242 1254 1302 1341 1296 1249 1240 1240 1234 1254 1246 1239 1256 1258 1245 1261 1256 1282 1275 1278 1311 1233 1287 1294 1308 1304 1278 1204 1209 1273 1289 1246 1262 1262 1312 1298 1287 1260 1281 1310 1244 1313 1205 1215 1251 1266 1228 1250 1284 1264 1270 1253 1244 1245 1280 1308 1262 1244 1248 1242 1239 1235 1224 1282 1280 1292 1278 1282 1284 1282 1258 1287 1255 1290 1302 1253 1303 1255 1265 1318 1245 1278 1282 1276 1332 1285 1264 1232 1269 1289 1247 1298 1244 1321 1283 1335 1300 1326 1346 1324 1272 1313 1258 1264 1245 1299 1267 1251 1244 1294 1309 1313 1274 1264 1306 1304 1286 1264 1270 1285 1297 1303 1317 1298 1286 1310 1297 1327 1306 1263 1293 1315 1311 1296 1282 1265 1309 1311 1295 1325 1289 1320 1298 1274 1314 1246 1354 1249 1295 1338 1299 1317 1315 1298 1312 1270 1262 1319 1291 1339 1305 1337 1349 1299 1287 1311 1354 1326 1280 1293 1317 1332 1313 1305 1336 1361 1335 1329 1309 1279 1304 1330 1330 1306 1344 1335 1337 1304 1295 1299 1310 1319 1368 1356 1357 1304 1298 1280 1349 1284 1300 1380 1339 1319 1282 1363 1282 1363 1357 1312 1338 1340 1325 1316 1314 1330 1331 1286 1338 1338 1347 1342 1291 1295 1322 1324 1320 1334 1345 1331 1325 1336 1329 1293 1289 1313 1328 1332 1355 1326 1356 1331 1336 1346 1360 1396 1389 1364 1361 1336 1310 1325 1297 1318 1327 1290 1332 1298 1370 1333 1374 1363 1400 1385 1342 1354 1406 1365 1293 1353 1319 1337 1395 1366 1366 1338 1361 1342 1337 1329 1354 1393 1359 1366 1395 1361 1354 1368 1415 1402 1375 1381 1374 1355 1386 1369 1326 1349 1360 1356 1336 1335 1355 1329 1313 1372 1357 1339 1393 1343 1350 1387 1346 1333 1347 1364 1350 1372 1385 1392 1525 1402 1413 1372 1437 1396 1355 1360 1383 1340 1289 1361 1341 1359 1343 1398 1341 1305 1377 1347 1348 1380 1359 1355 1383 1407 1360 1350 1376 1413 1399 1346 1356 1396 1388 1371 1377 1383 1411 1407 1361 1363 1357 1377 1374 1344 1354 1342 1362 1396 1346 1424 1350 1365 1383 1376 1404 1387 1339 1375 1386 1393 1439 1387 1398 1422 1406 1379 1384 1419 1393 1385 1430 1441 1409 1384 1411 1378 1368 1385 1409 1421 1398 1416 1427 1408 1376 1387 1409 1384 1370 1358 1386 1427 1403 1391 1414 1394 1429 1412 1423 1391 1396 1413 1346 1394 1400 1422 1405 1376 1367 1349 1419 1439 1394 1444 1411 1412 1422 1405 1457 1378 1451 1389 1375 1417 1388 1384 1450 1422 1432 1416 1380 1385 1402 1443 1417 1394 1407 1432 1426 1421 1436 1452 1481 1477 1454 1408 1420 1437 1450 1430 1395 1401 1433 1465 1453 1484 1452 1430 1398 1391 1402 1415 1444 1403 1385 1479 1475 1420 1451 1410 1455 1415 1370 1446 1439 1448 1399 1428 1403 1421 1415 1413 1461 1425 1447 1431 1401 1435 1409 1437 1453 1459 1459 1451 1431 1441 1459 1431 1423 1457 1458 1429 1434 1436 1442 1418 1392 1392 1416 1458 1491 1431 1356 1400 1414 1438 1468 1485 1451 1447 1425 1439 1482 1479 1478 1455 1407 1443 1474 1453 1450 1462 1480 1408 1419 1486 1468 1398 1446 1440 1481 1414 1479 1415 1443 1450 1459 1413 1441 1458 1458 1470 1455 1478 1461 1453 1479 1438 1424 1445 1445 1454 1454 1434 1440 1424 1422 1459 1509 1490 1500 1486 1495 1483 1451 1458 1486 1460 1517 1489 1437 1415 1450 1508 1539 1461 1416 1442 1607 1458 1522 1454 1452 1456 1472 1530 1481 1421 1473 1515 1478 1500 1426 1455 1495 1514 1491 1493 1536 1510 1513 1516 1522 1505 1506 1522 1512 1504 1509 1499 1511 1504 1511 1532 1542 1502 1523 1520 1515 1517 1541 1515 1506 1520 1514 1550 1530 1529 1531 1555 1552 1540 1535 1507 1532 1510 1567 1539 1543 1569 1518 1477 1568 1527 1545 1603 1579 1615 1627 1543 1551 1525 1527 1531 1550 1545 1537 1532 1580 1612 1616 1590 1559 1555 1589 1632 1622 1627 1742 1841 1852 1834 1923 2043 2099 2170 2178 2282 2513 2905 3546 4711 6810 10367 15701 20523 21500 19225 15934 12597 10595 8441 6447 4555 3623 2845 2615 2276 2036 1881 1677 1748 1715 1691 1776 1772 1807 1810 1711 1731 1654 1625 1624 1635 1623 1592 1620 1619 1598 1602 1606 1609 1601 1559 1554 1587 1568 1599 1578 1525 1566 1517 1547 1584 1573 1578 1626 1534 1526 1557 1548 1574 1586 1569 1525 1607 1576 1552 1549 1574 1562 1591 1532 1572 1476 1613 1538 1535 1550 1577 1539 1551 1495 1530 1579 1550 1544 1525 1514 1518 1549 1580 1563 1531 1547 1563 1555 1562 1548 1530 1562 1552 1567 1602 1535 1517 1542 1545 1565 1581 1546 1510 1544 1562 1592 1576 1545 1594 1581 1582 1665 1590 1698 1686 1614 1611 1676 1562 1539 1582 1572 1549 1577 1526 1568 1543 1582 1566 1542 1598 1562 1535 1518 1552 1520 1499 1554 1562 1555 1589 1598 1594 1551 1522 1513 1532 1525 1525 1528 1539 1520 1508 1535 1553 1529 1518 1542 1558 1523 1535 1529 1511 1545 1543 1529 1552 1581 1569 1548 1549 1479 1541 1499 1590 1490 1553 1587 1489 1517 1522 1512 1555 1538 1521 1528 1531 1544 1551 1534 1537 1572 1576 1531 1476 1541 1553 1516 1541 1553 1514 1520 1537 1533 1543 1568 1542 1501 1560 1605 1558 1536 1519 1509 1499 1549 1571 1513 1561 1572 1507 1495 1546 1542 1539 1535 1522 1526 1560 1574 1591 1596 1516 1568 1508 1555 1502 1445 1531 1553 1520 1521 1520 1547 1537 1569 1528 1511 1503 1537 1520 1546 1552 1530 1515 1570 1554 1519 1537 1524 1485 1498 1530 1511 1548 1566 1524 1483 1492 1531 1540 1541 1514 1513 1541 1505 1540 1474 1477 1540 1539 1521 1560 1493 1529 1506 1502 1489 1530 1563 1546 1554 1485 1488 1517 1574 1488 1515 1498 1477 1580 1537 1496 1555 1587 1539 1554 1567 1602 1537 1581 1670 1649 1573 1580 1597 1581 1588 1589 1595 1597 1592 1565 1594 1629 1575 1549 1569 1603 1585 1565 1571 1631 1695 1604 1607 1606 1644 1781 1644 1577 1588 1595 1606 1640 1609 1616 1619 1630 1653 1573 1662 1626 1588 1742 1621 1614 1630 1672 1615 1592 1652 1620 1654 1670 1648 1625 1612 1634 1635 1720 1668 1637 1673 1755 1678 1649 1675 1688 1640 1625 1647 1670 1663 1639 1667 1714 1688 1666 1681 1767 1692 1662 1781 1856 1907 1957 2120 2189 2330 2522 2533 2743 2923 2951 3041 3143 3471 4057 4832 6500 9899 16134 25880 39369 52587 58999 56602 48760 39005 29717 21987 14642 9748 6705 4800 4089 3779 3348 3259 3132 2815 2598 2499 2226 1950 1940 1843 1727 1779 1740 1701 1792 1837 1818 1849 1870 1725 1777 1767 1672 1665 1681 1660 1682 1680 1697 1691 1735 1695 1704 1582 1631 1643 1634 1612 1595 1590 1713 1690 1640 1645 1605 1590 1578 1612 1611 1611 1591 1625 1630 1603 1631 1608 1623 1614 1582 1607 1605 1605 1571 1552 1579 1569 1594 1575 1543 1561 1610 1628 1621 1581 1590 1566 1568 1550 1556 1572 1570 1555 1579 1553 1560 1598 1551 1582 1528 1566 1610 1562 1553 1551 1549 1579 1594 1567 1541 1545 1602 1543 1560 1539 1591 1554 1556 1568 1574 1552 1618 1553 1573 1550 1527 1539 1559 1577 1551 1551 1552 1555 1604 1591 1538 1482 1518 1571 1579 1567 1554 1569 1579 1560 1527 1556 1549 1556 1553 1540 1544 1529 1510 1507 1485 1593 1527 1550 1546 1593 1557 1495 1527 1508 1532 1516 1497 1538 1580 1508 1545 1514 1532 1506 1495 1488 1557 1558 1503 1510 1525 1521 1528 1517 1520 1521 1523 1560 1548 1522 1527 1581 1575 1544 1578 1598 1565 1555 1596 1538 1515 1520 1509 1524 1519 1511 1565 1591 1542 1547 1531 1546 1508 1492 1513 1549 1589 1541 1568 1509 1538 1538 1521 1536 1479 1577 1558 1491 1533 1471 1535 1482 1526 1520 1563 1540 1535 1533 1531 1528 1554 1572 1504 1562 1562 1546 1559 1531 1493 1500 1538 1537 1540 1581 1571 1543 1544 1559 1577 1583 1539 1572 1562 1545 1558 1576 1546 1572 1567 1559 1509 1552 1514 1511 1579 1549 1543 1549 1505 1565 1507 1498 1557 1496 1536 1508 1492 1498 1554 1496 1558 1496 1515 1565 1565 1509 1495 1499 1538 1561 1532 1531 1531 1521 1492 1474 1505 1517 1517 1530 1528 1528 1506 1516 1554 1547 1545 1525 1538 1503 1534 1542 1502 1505 1495 1505 1547 1538 1450 1471 1518 1475 1542 1512 1508 1523 1506 1527 1567 1494 1510 1506 1519 1550 1479 1544 1534 1505 1538 1482 1469 1464 1502 1517 1485 1467 1468 1453 1489 1524 1515 1508 1511 1543 1532 1509 1537 1564 1541 1526 1510 1492 1496 1524 1510 1475 1504 1558 1574 1490 1530 1529 1523 1469 1513 1506 1497 1530 1515 1527 1529 1490 1520 1533 1513 1491 1510 1534 1455 1452 1481 1499 1527 1537 1469 1469 1432 1477 1522 1502 1512 1587 1494 1512 1495 1515 1537 1538 1508 1505 1501 1519 1505 1508 1482 1484 1555 1563 1517 1502 1523 1527 1470 1488 1526 1510 1492 1524 1495 1485 1510 1513 1511 1527 1509 1495 1508 1486 1471 1540 1522 1484 1472 1497 1525 1523 1505 1497 1498 1503 1527 1487 1530 1526 1547 1511 1521 1528 1529 1534 1501 1493 1493 1531 1550 1515 1512 1518 1531 1513 1494 1510 1532 1536 1514 1537 1514 1498 1492 1500 1505 1487 1491 1555 1528 1502 1488 1538 1516 1509 1542 1470 1530 1495 1485 1467 1488 1536 1469 1532 1483 1475 1528 1498 1557 1536 1454 1502 1546 1512 1509 1523 1512 1528 1527 1488 1479 1500 1531 1547 1523 1501 1489 1508 1536 1515 1520 1488 1507 1502 1529 1540 1474 1478 1497 1537 1516 1513 1517 1486 1457 1488 1527 1534 1514 1537 1451 1537 1506 1556 1523 1520 1541 1503 1516 1504 1453 1498 1504 1508 1548 1499 1496 1526 1478 1496 1490 1530 1510 1525 1513 1503 1526 1479 1496 1526 1516 1512 1531 1530 1491 1522 1527 1489 1517 1552 1542 1552 1532 1527 1518 1526 1529 1475 1469 1456 1470 1536 1476 1462 1484 1509 1512 1528 1501 1452 1512 1491 1505 1492 1520 1520 1498 1494 1535 1546 1544 1545 1535 1490 1524 1550 1486 1517 1527 1501 1496 1526 1605 1543 1497 1472 1486 1514 1545 1482 1474 1517 1554 1501 1481 1499 1541 1502 1515 1512 1494 1491 1494 1473 1478 1545 1542 1496 1533 1554 1518 1551 1545 1495 1544 1520 1541 1515 1533 1507 1503 1524 1525 1557 1459 1493 1467 1502 1530 1491 1555 1545 1497 1463 1564 1441 1481 1539 1496 1519 1483 1461 1451 1471 1452 1490 1528 1517 1498 1507 1514 1528 1483 1448 1503 1504 1488 1496 1501 1487 1492 1513 1515 1523 1496 1474 1506 1503 1503 1524 1534 1508 1517 1518 1505 1490 1515 1489 1470 1530 1528 1539 1478 1465 1473 1464 1524 1527 1549 1501 1484 1508 1473 1519 1504 1483 1523 1435 1465 1474 1504 1525 1507 1514 1513 1500 1546 1524 1499 1488 1523 1506 1466 1481 1511 1521 1502 1500 1516 1506 1484 1497 1539 1525 1512 1548 1501 1470 1490 1505 1504 1509 1510 1476 1503 1521 1528 1487 1533 1512 1530 1512 1502 1430 1443 1525 1544 1534 1550 1482 1524 1510 1574 1512 1489 1565 1515 1508 1536 1513 1541 1500 1556 1546 1520 1527 1493 1509 1532 1507 1513 1531 1543 1534 1528 1544 1511 1516 1539 1532 1510 1522 1505 1520 1526 1528 1495 1519 1509 1489 1493 1523 1488 1562 1512 1558 1532 1529 1539 1532 1513 1512 1525 1516 1531 1525 1493 1544 1505 1534 1499 1533 1489 1480 1521 1472 1499 1535 1467 1508 1486 1474 1511 1511 1497 1517 1494 1515 1513 1512 1529 1517 1502 1504 1495 1479 1491 1507 1496 1525 1520 1521 1526 1479 1503 1526 1504 1457 1512 1531 1529 1490 1440 1455 1540 1554 1539 1571 1511 1531 1519 1542 1556 1450 1542 1485 1466 1517 1547 1527 1482 1488 1509 1459 1527 1547 1528 1452 1487 1485 1515 1510 1537 1508 1493 1541 1532 1533 1526 1509 1533 1532 1526 1500 1487 1483 1488 1531 1542 1540 1497 1536 1543 1519 1494 1525 1544 1498 1505 1567 1510 1534 1527 1550 1518 1486 1545 1518 1543 1525 1519 1556 1571 1499 1489 1544 1526 1492 1476 1571 1536 1516 1545 1528 1542 1509 1469 1448 1479 1511 1514 1529 1556 1530 1503 1502 1513 1527 1522 1507 1527 1536 1527 1482 1496 1514 1480 1490 1517 1494 1522 1560 1546 1552 1553 1549 1561 1536 1512 1501 1533 1528 1512 1555 1557 1489 1473 1519 1465 1496 1514 1468 1443 1528 1539 1499 1462 1497 1564 1475 1466 1494 1517 1501 1547 1546 1534 1519 1514 1535 1564 1533 1493 1496 1500 1516 1551 1539 1512 1474 1515 1525 1476 1484 1509 1509 1503 1498 1492 1525 1494 1539 1507 1481 1558 1514 1490 1524 1514 1547 1557 1552 1553 1539 1536 1507 1531 1521 1506 1511 1533 1514 1469 1542 1509 1491 1558 1568 1560 1525 1555 1516 1520 1529 1502 1523 1548 1533 1484 1500 1504 1509 1544 1533 1511 1518 1538 1519 1528 1547 1544 1581 1550 1535 1547 1583 1562 1567 1498 1513 1520 1533 1483 1490 1481 1497 1525 1520 1497 1449 1506 1529 1499 1498 1514 1547 1566 1521 1534 1519 1556 1530 1590 1546 1518 1535 1508 1505 1498 1522 1562 1534 1557 1537 1521 1531 1543 1529 1545 1540 1534 1531 1508 1531 1546 1560 1527 1491 1529 1556 1570 1566 1519 1559 1489 1501 1542 1506 1508 1528 1555 1482 1553 1505 1511 1529 1564 1539 1539 1563 1532 1528 1555 1576 1594 1579 1536 1555 1549 1572 1559 1550 1529 1465 1509 1569 1551 1566 1584 1585 1557 1529 1548 1606 1593 1579 1561 1554 1557 1525 1533 1559 1537 1529 1577 1562 1576 1561 1540 1523 1577 1599 1544 1630 1565 1559 1550 1547 1520 1580 1558 1565 1526 1596 1585 1564 1512 1537 1527 1541 1591 1604 1560 1600 1576 1569 1576 1603 1599 1609 1590 1626 1601 1556 1540 1555 1604 1570 1585 1575 1561 1573 1555 1540 1584 1609 1613 1623 1569 1573 1592 1595 1549 1544 1582 1603 1554 1612 1655 1600 1560 1582 1615 1583 1520 1602 1623 1559 1621 1629 1588 1594 1570 1585 1635 1531 1574 1597 1590 1641 1572 1608 1610 1575 1613 1616 1597 1556 1585 1561 1569 1581 1612 1626 1608 1616 1600 1596 1619 1618 1612 1591 1584 1611 1639 1617 1617 1662 1623 1611 1638 1617 1649 1631 1604 1667 1671 1687 1814 1818 1863 1848 1951 1896 2033 2112 2065 2125 2078 2136 2107 2152 2205 2394 2359 2522 2878 3509 4617 6844 10913 17753 24737 28719 27531 23811 18400 13492 9116 6506 4685 3639 3089 2800 2405 2133 2190 2221 2046 1968 2010 2007 1918 1940 1836 1804 1832 1863 1883 1757 1704 1674 1644 1629 1632 1622 1584 1649 1736 1646 1618 1631 1631 1666 1640 1594 1619 1612 1628 1595 1542 1610 1723 1688 1628 1717 1707 1618 1638 1643 1555 1628 1631 1608 1610 1621 1581 1636 1583 1572 1609 1610 1592 1613 1578 1571 1604 1595 1587 1586 1606 1627 1652 1723 1639 1614 1579 1568 1551 1593 1583 1571 1631 1603 1615 1596 1572 1601 1539 1602 1567 1637 1598 1576 1555 1611 1576 1539 1535 1608 1598 1579 1524 1572 1550 1569 1525 1612 1574 1559 1570 1622 1583 1621 1556 1539 1580 1586 1557 1560 1585 1602 1580 1546 1600 1591 1600 1598 1570 1573 1564 1585 1608 1591 1579 1575 1556 1555 1592 1612 1578 1552 1542 1579 1574 1571 1551 1542 1615 1573 1543 1560 1609 1615 1601 1574 1544 1595 1586 1606 1610 1561 1571 1586 1575 1529 1568 1539 1556 1600 1569 1560 1592 1529 1559 1611 1613 1583 1540 1557 1541 1532 1547 1571 1600 1559 1538 1573 1524 1528 1546 1506 1543 1571 1575 1572 1596 1559 1571 1581 1584 1577 1546 1526 1560 1582 1543 1632 1543 1576 1564 1528 1553 1573 1555 1497 1537 1567 1555 1557 1513 1539 1566 1561 1554 1555 1580 1562 1542 1537 1532 1589 1593 1613 1581 1605 1583 1546 1593 1614 1559 1549 1560 1551 1547 1552 1551 1559 1558 1563 1575 1548 1541 1518 1561 1559 1571 1548 1574 1586 1558 1551 1613 1577 1575 1586 1541 1569 1520 1553 1572 1569 1532 1538 1590 1666 1596 1615 1605 1583 1555 1510 1550 1546 1577 1569 1551 1540 1538 1566 1544 1548 1557 1563 1574 1593 1615 1606 1570 1550 1563 1588 1589 1594 1584 1597 1582 1603 1672 1608 1578 1564 1571 1562 1529 1580 1556 1557 1534 1574 1585 1592 1564 1573 1583 1590 1600 1619 1552 1567 1700 1616 1708 1543 1529 1554 1561 1561 1547 1525 1556 1595 1533</intensities>
			</dataPoints>
			<nonAmbientPoints type="Temperature" unit="K">
				<measurementTimes unit="seconds" deltaTime="1">0</measurementTimes>
				<nonAmbientValues>298.000</nonAmbientValues>
			</nonAmbientPoints>
		</scan>
	</xrdMeasurement>
</xrdMeasurements>