File: Result/Raw data/XRD_550C_raw/SAMPLE_7_COPPER_30mins_550C.XRDML striped k alpha 2.XRDML
<?xml version="1.0" encoding="UTF-8"?>
<xrdMeasurements xmlns="http://www.xrdml.com/XRDMeasurement/1.5" xmlns:xsi="http://www.w3.org/2001/XMLSchema-instance" xsi:schemaLocation="http://www.xrdml.com/XRDMeasurement/1.5 http://www.xrdml.com/XRDMeasurement/1.5/XRDMeasurement.xsd" status="Completed">
	<comment>
		<entry>Configuration=Flat Sample Stage, Owner=User-1, Creation date=3/25/2015 2:10:01 PM</entry>
		<entry>Goniometer=PW3050/60 (Theta/Theta); Minimum step size 2Theta:0.001; Minimum step size Omega:0.001</entry>
		<entry>Sample stage=PW3071/xx Bracket</entry>
		<entry>Diffractometer system=XPERT-PRO</entry>
		<entry>Measurement program=C:\PANalytical\Data Collector\Programs\Flat sample Scan.xrdmp, Identifier={A9F6D0C0-202E-4C59-A4F1-A5BA86123012}</entry>
		<entry/>
	</comment>
	<xrdMeasurement measurementType="Scan" status="Completed" sampleMode="Reflection">
		<usedWavelength intended="K-Alpha 1">
			<kAlpha1 unit="Angstrom">1.540598</kAlpha1>
			<kAlpha2 unit="Angstrom">1.544426</kAlpha2>
			<kBeta unit="Angstrom">1.392250</kBeta>
			<ratioKAlpha2KAlpha1>0.000000</ratioKAlpha2KAlpha1>
		</usedWavelength>
		<incidentBeamPath>
			<radius unit="mm">240.000</radius>
			<xRayTube>
				<tension unit="kV">40</tension>
				<current unit="mA">30</current>
				<anodeMaterial>Cu</anodeMaterial>
			</xRayTube>
			<divergenceSlit xsi:type="fixedDivergenceSlitType">
				<angle unit="deg">0.500</angle>
			</divergenceSlit>
		</incidentBeamPath>
		<diffractedBeamPath>
			<radius unit="mm">240.000</radius>
			<receivingSlit>
				<height unit="mm">0.100</height>
			</receivingSlit>
		</diffractedBeamPath>
		<scan appendNumber="0" mode="Continuous" scanAxis="Gonio" status="Completed">
			<header>
				<startTimeStamp>2020-02-27T18:09:20</startTimeStamp>
				<author>
					<name>user-1</name>
				</author>
				<source>
					<applicationSoftware version="4.1.0">HighScore</applicationSoftware>
				</source>
			</header>
			<dataPoints>
				<positions axis="2Theta" unit="deg">
					<startPosition>20.008</startPosition>
					<endPosition>79.984</endPosition>
				</positions>
				<commonCountingTime unit="seconds">34.925</commonCountingTime>
				<intensities unit="counts">988 1006 1005 1007 1015 1067 1033 991 978 1028 993 1023 1022 1022 988 1055 1031 990 1023 1027 1027 1053 1034 999 1012 1038 1055 1052 1043 1027 996 1040 1032 1003 1041 1028 1052 1062 1015 1020 1042 1078 1070 1027 1045 1039 1022 1046 1028 1044 1062 1038 1062 1048 1030 1065 1041 1017 1057 1027 1058 1000 1086 1072 1022 1027 1012 1056 1057 1029 1039 1025 1046 1060 1061 1059 1035 1040 1039 1050 1050 1037 1040 1039 1064 1051 1018 1048 1050 1035 1062 1064 1068 1057 1061 1081 1089 1041 1030 1034 1048 1063 1032 1050 1030 1068 1050 1024 1051 1096 1054 1078 1071 1088 1052 1071 1077 1082 1102 1065 1042 1083 1095 1072 1044 1097 1041 1090 1100 1119 1071 1087 1085 1056 1059 1132 1127 1078 1068 1067 1081 1100 1107 1093 1080 1082 1084 1078 1101 1109 1084 1063 1083 1105 1083 1096 1073 1068 1078 1089 1107 1090 1109 1119 1090 1079 1098 1114 1103 1071 1084 1103 1092 1089 1090 1108 1098 1120 1037 1079 1119 1154 1098 1059 1084 1095 1081 1112 1126 1074 1135 1156 1113 1103 1099 1065 1056 1058 1083 1111 1108 1065 1098 1125 1117 1097 1116 1110 1084 1083 1078 1090 1086 1080 1090 1080 1130 1112 1106 1136 1144 1165 1128 1130 1161 1149 1115 1151 1115 1105 1159 1166 1110 1134 1118 1088 1175 1123 1076 1147 1117 1101 1100 1119 1111 1132 1156 1127 1108 1122 1145 1103 1149 1144 1138 1174 1180 1150 1145 1130 1140 1137 1145 1162 1140 1113 1140 1131 1087 1110 1132 1114 1113 1138 1132 1105 1125 1139 1116 1098 1147 1149 1108 1106 1147 1130 1136 1101 1168 1178 1134 1146 1139 1112 1126 1119 1167 1150 1161 1115 1146 1167 1179 1151 1134 1166 1161 1152 1128 1158 1165 1180 1183 1160 1113 1110 1157 1176 1156 1166 1199 1190 1154 1161 1172 1197 1205 1175 1165 1163 1162 1162 1175 1163 1157 1145 1175 1149 1167 1217 1156 1163 1139 1173 1169 1225 1153 1191 1175 1146 1167 1200 1188 1148 1152 1171 1203 1176 1203 1210 1185 1157 1160 1166 1191 1235 1164 1167 1173 1168 1175 1197 1208 1164 1197 1190 1180 1200 1193 1198 1188 1174 1176 1162 1157 1157 1190 1188 1168 1201 1188 1195 1178 1172 1220 1203 1199 1211 1171 1141 1168 1190 1141 1236 1211 1191 1202 1199 1222 1222 1214 1229 1201 1203 1200 1223 1175 1246 1219 1234 1173 1214 1228 1217 1192 1207 1182 1159 1202 1221 1206 1189 1168 1161 1229 1238 1215 1222 1195 1203 1204 1199 1204 1207 1237 1306 1229 1203 1224 1203 1157 1221 1203 1217 1196 1207 1166 1182 1273 1211 1174 1196 1207 1199 1242 1219 1200 1142 1152 1184 1202 1210 1190 1215 1182 1211 1201 1217 1239 1212 1200 1215 1210 1229 1228 1219 1187 1210 1214 1229 1227 1214 1192 1226 1237 1223 1228 1219 1265 1263 1219 1241 1253 1249 1255 1214 1241 1242 1252 1251 1230 1228 1275 1201 1223 1217 1276 1230 1226 1272 1233 1251 1220 1264 1236 1198 1262 1262 1286 1240 1220 1284 1235 1232 1284 1311 1233 1238 1230 1268 1256 1208 1197 1219 1247 1263 1268 1237 1236 1232 1228 1232 1241 1274 1270 1237 1250 1297 1277 1271 1268 1251 1266 1289 1269 1281 1228 1204 1285 1287 1262 1437 1256 1239 1239 1282 1281 1290 1249 1267 1255 1256 1266 1232 1285 1258 1268 1305 1255 1292 1293 1279 1247 1265 1292 1285 1258 1244 1242 1257 1280 1265 1239 1270 1306 1294 1282 1279 1274 1275 1251 1266 1292 1299 1287 1274 1255 1238 1246 1243 1266 1252 1220 1261 1239 1249 1277 1258 1269 1232 1303 1235 1270 1244 1304 1282 1299 1208 1257 1282 1247 1284 1270 1301 1275 1285 1306 1304 1255 1287 1277 1275 1272 1252 1274 1236 1283 1330 1283 1285 1289 1301 1280 1268 1306 1309 1307 1310 1346 1301 1268 1281 1277 1290 1330 1329 1337 1323 1271 1273 1334 1313 1319 1285 1273 1264 1274 1301 1309 1296 1304 1310 1294 1324 1280 1266 1309 1256 1316 1235 1306 1282 1270 1335 1315 1256 1275 1318 1273 1240 1261 1313 1312 1273 1317 1320 1284 1298 1337 1301 1274 1303 1332 1327 1287 1278 1309 1322 1330 1309 1285 1296 1322 1324 1321 1309 1329 1316 1350 1328 1261 1283 1297 1367 1310 1302 1343 1324 1313 1344 1329 1322 1306 1332 1348 1307 1315 1302 1332 1356 1359 1292 1341 1330 1292 1305 1308 1307 1339 1290 1291 1299 1324 1314 1290 1288 1321 1337 1280 1271 1302 1313 1340 1354 1325 1342 1303 1295 1297 1306 1346 1347 1327 1336 1312 1297 1319 1342 1336 1340 1370 1327 1318 1320 1298 1319 1332 1343 1297 1334 1382 1351 1330 1310 1367 1364 1360 1335 1305 1319 1362 1372 1266 1329 1337 1366 1341 1307 1316 1345 1314 1340 1347 1336 1314 1346 1338 1327 1307 1322 1319 1324 1333 1342 1339 1319 1342 1323 1322 1323 1308 1327 1326 1366 1318 1347 1388 1366 1294 1296 1322 1312 1321 1332 1365 1303 1318 1370 1365 1359 1284 1359 1342 1375 1349 1318 1295 1339 1331 1359 1358 1355 1386 1374 1374 1323 1348 1405 1366 1346 1369 1377 1371 1327 1348 1344 1349 1368 1343 1366 1371 1362 1343 1358 1404 1366 1351 1365 1385 1320 1332 1351 1370 1374 1328 1372 1381 1368 1289 1332 1366 1407 1370 1370 1337 1344 1389 1343 1368 1311 1377 1452 1364 1363 1340 1381 1406 1353 1372 1411 1366 1328 1348 1378 1386 1416 1385 1383 1348 1322 1357 1360 1346 1356 1388 1388 1367 1367 1367 1375 1361 1396 1382 1327 1366 1414 1374 1353 1366 1355 1373 1402 1389 1408 1377 1402 1386 1386 1344 1348 1419 1375 1364 1397 1350 1381 1320 1355 1392 1389 1399 1371 1365 1354 1405 1398 1367 1357 1375 1371 1355 1349 1351 1367 1420 1409 1385 1396 1393 1389 1399 1358 1344 1377 1376 1390 1405 1369 1379 1380 1375 1430 1431 1386 1397 1392 1381 1370 1395 1402 1388 1366 1370 1402 1400 1403 1346 1363 1415 1424 1430 1324 1442 1391 1363 1428 1387 1420 1389 1374 1417 1383 1370 1394 1391 1409 1365 1364 1335 1401 1404 1408 1391 1373 1426 1425 1409 1418 1400 1377 1393 1400 1402 1416 1369 1380 1405 1382 1435 1405 1401 1395 1403 1371 1392 1402 1411 1420 1408 1412 1406 1459 1366 1384 1409 1438 1398 1395 1388 1453 1439 1459 1370 1456 1398 1399 1430 1413 1528 1462 1436 1456 1418 1417 1446 1467 1427 1434 1445 1447 1412 1436 1421 1440 1460 1427 1466 1449 1384 1389 1403 1391 1419 1434 1459 1466 1437 1431 1461 1427 1420 1395 1387 1468 1443 1409 1445 1414 1394 1435 1409 1443 1435 1414 1385 1420 1399 1376 1455 1369 1423 1402 1478 1406 1398 1406 1405 1419 1463 1356 1434 1444 1460 1418 1430 1440 1442 1464 1461 1394 1414 1440 1447 1437 1411 1430 1425 1453 1419 1403 1435 1450 1440 1444 1454 1423 1417 1437 1416 1390 1391 1386 1447 1470 1457 1452 1443 1433 1438 1426 1355 1397 1431 1454 1436 1441 1430 1428 1483 1416 1492 1414 1479 1462 1470 1433 1475 1449 1467 1429 1435 1461 1447 1448 1438 1470 1454 1416 1391 1404 1431 1485 1446 1439 1449 1467 1482 1469 1456 1461 1477 1457 1497 1480 1463 1430 1452 1474 1423 1417 1412 1426 1493 1549 1503 1473 1441 1465 1403 1538 1445 1448 1428 1481 1507 1440 1473 1493 1443 1428 1463 1529 1499 1522 1510 1476 1497 1539 1554 1526 1503 1480 1531 1521 1519 1506 1527 1568 1520 1494 1504 1510 1550 1543 1548 1653 1584 1551 1525 1552 1495 1498 1560 1495 1474 1546 1589 1551 1536 1563 1569 1515 1544 1539 1555 1562 1528 1553 1557 1519 1492 1522 1521 1560 1608 1558 1531 1563 1714 1579 1558 1571 1619 1551 1570 1555 1554 1605 1648 1634 1726 1775 1813 1826 1820 1898 2000 2103 2224 2341 2584 2802 3187 3760 4631 6203 8440 11660 15808 21860 29186 33205 29945 22711 16340 12072 9679 8346 7421 6254 5385 4629 4157 3392 2813 2450 2169 2138 1887 1889 1879 2017 1870 1926 1752 1654 1722 1675 1549 1604 1612 1624 1647 1600 1612 1624 1587 1581 1524 1553 1579 1570 1561 1566 1570 1605 1570 1548 1578 1590 1579 1567 1580 1579 1590 1598 1590 1593 1581 1561 1614 1566 1529 1559 1554 1515 1554 1554 1604 1554 1569 1517 1576 1494 1546 1528 1524 1565 1589 1523 1538 1526 1555 1625 1549 1560 1542 1552 1576 1558 1548 1571 1562 1523 1525 1554 1535 1553 1555 1558 1561 1556 1533 1572 1565 1569 1568 1554 1549 1546 1558 1576 1543 1569 1579 1581 1591 1688 1711 1745 1671 1647 1581 1627 1616 1569 1549 1529 1493 1547 1586 1520 1560 1583 1535 1543 1575 1544 1578 1514 1536 1532 1524 1551 1568 1569 1565 1566 1486 1569 1580 1517 1512 1530 1511 1505 1507 1527 1566 1526 1508 1520 1519 1546 1561 1554 1549 1512 1539 1559 1513 1508 1496 1531 1571 1590 1587 1511 1549 1552 1516 1555 1491 1507 1565 1591 1565 1532 1526 1546 1552 1555 1555 1485 1614 1542 1516 1525 1548 1540 1544 1567 1568 1512 1529 1552 1503 1532 1534 1542 1546 1579 1550 1553 1534 1553 1558 1565 1590 1587 1559 1543 1546 1538 1541 1576 1552 1558 1587 1567 1574 1594 1548 1518 1498 1514 1513 1530 1562 1509 1463 1504 1521 1527 1546 1533 1536 1566 1511 1566 1600 1569 1533 1487 1540 1554 1515 1556 1531 1555 1545 1508 1552 1574 1543 1546 1506 1508 1550 1561 1556 1559 1494 1518 1581 1546 1527 1549 1542 1554 1543 1534 1562 1560 1539 1556 1552 1532 1545 1534 1512 1525 1561 1512 1527 1535 1549 1583 1611 1590 1567 1563 1593 1559 1517 1623 1611 1587 1550 1506 1545 1530 1606 1576 1703 1640 1623 1784 1777 1624 1662 1631 1596 1649 1647 1671 1637 1651 1739 1662 1660 1648 1649 1678 1669 1670 1666 1650 1631 1635 1650 1675 1664 1677 1663 1647 1687 1605 1621 1627 1632 1701 1677 1673 1716 1689 1696 1671 1660 1698 1692 1662 1657 1696 1666 1680 1728 1681 1653 1677 1684 1677 1688 1715 1707 1699 1685 1714 1737 1729 1644 1641 1687 1714 1729 1721 1729 1833 1742 1740 1764 1810 1903 1880 1846 1886 1865 1884 2047 2138 2156 2320 2501 2707 2894 3052 3205 3332 3658 3696 4037 4817 5645 7416 10490 15128 22327 33238 48741 65798 75167 68380 52325 36580 23859 15554 11033 8542 6895 5700 5318 4525 4273 3599 3274 2828 2753 2411 2032 2059 1902 1988 1950 1971 1890 1936 2028 1951 2000 1915 1862 1728 1770 1787 1767 1772 1757 1738 1728 1752 1842 1776 1736 1747 1719 1717 1731 1683 1607 1696 1695 1676 1657 1641 1685 1690 1685 1693 1719 1559 1684 1624 1662 1701 1609 1641 1637 1698 1657 1653 1668 1645 1675 1658 1655 1666 1603 1627 1655 1668 1638 1629 1631 1654 1639 1587 1606 1612 1613 1626 1624 1617 1644 1632 1585 1591 1615 1599 1556 1566 1607 1594 1630 1642 1585 1581 1616 1616 1646 1619 1611 1597 1581 1551 1615 1616 1628 1622 1565 1521 1625 1574 1588 1631 1586 1589 1566 1627 1556 1579 1582 1586 1581 1613 1673 1637 1610 1595 1614 1606 1593 1601 1622 1656 1627 1603 1566 1557 1582 1597 1626 1615 1608 1609 1573 1567 1568 1615 1608 1565 1578 1602 1636 1575 1612 1565 1584 1584 1602 1557 1560 1576 1600 1592 1631 1622 1623 1612 1548 1585 1610 1621 1540 1610 1566 1565 1573 1559 1560 1590 1564 1521 1592 1577 1614 1555 1601 1588 1546 1551 1551 1570 1572 1591 1553 1594 1621 1578 1582 1578 1543 1567 1581 1540 1544 1587 1569 1604 1596 1585 1612 1569 1562 1609 1616 1614 1658 1551 1550 1572 1553 1592 1550 1559 1526 1595 1583 1585 1523 1594 1601 1574 1557 1607 1610 1651 1550 1553 1621 1576 1533 1586 1600 1596 1553 1598 1624 1621 1705 1737 1678 1604 1599 1608 1606 1612 1622 1609 1610 1643 1628 1587 1593 1570 1581 1580 1606 1593 1572 1558 1591 1728 1515 1512 1540 1609 1571 1635 1560 1587 1637 1606 1492 1594 1569 1574 1555 1560 1560 1534 1621 1600 1532 1540 1589 1579 1582 1618 1534 1557 1565 1554 1579 1584 1592 1567 1538 1540 1595 1593 1568 1584 1591 1557 1551 1563 1600 1532 1500 1545 1593 1611 1564 1527 1548 1546 1568 1610 1594 1550 1559 1535 1567 1567 1567 1624 1588 1578 1499 1536 1575 1593 1513 1583 1573 1553 1602 1548 1560 1579 1571 1584 1558 1531 1552 1577 1590 1599 1578 1581 1601 1565 1581 1561 1535 1540 1589 1619 1600 1578 1561 1610 1600 1582 1532 1529 1565 1566 1553 1533 1541 1601 1575 1543 1550 1561 1569 1571 1613 1559 1557 1604 1561 1533 1564 1618 1625 1595 1554 1561 1556 1577 1559 1543 1558 1622 1614 1509 1568 1550 1587 1561 1553 1555 1546 1561 1578 1497 1474 1572 1604 1576 1561 1564 1589 1551 1530 1575 1579 1572 1565 1557 1560 1532 1556 1588 1570 1556 1535 1555 1595 1588 1594 1589 1631 1613 1551 1547 1539 1556 1571 1569 1566 1533 1528 1590 1542 1561 1561 1551 1566 1606 1581 1495 1543 1544 1576 1553 1572 1562 1595 1536 1550 1588 1531 1555 1599 1580 1552 1560 1542 1551 1562 1563 1578 1585 1546 1536 1577 1564 1522 1568 1574 1573 1543 1525 1540 1586 1533 1529 1564 1536 1548 1541 1578 1540 1541 1543 1588 1580 1590 1552 1544 1543 1547 1545 1532 1548 1542 1535 1540 1567 1488 1608 1531 1560 1563 1561 1547 1579 1537 1515 1558 1568 1560 1553 1571 1585 1605 1584 1572 1555 1564 1571 1574 1582 1559 1546 1522 1534 1526 1504 1530 1561 1550 1554 1571 1580 1579 1536 1572 1603 1565 1521 1523 1547 1549 1589 1562 1494 1528 1623 1597 1560 1527 1561 1580 1561 1549 1546 1596 1528 1536 1506 1585 1603 1565 1598 1539 1590 1544 1576 1576 1549 1542 1560 1591 1566 1547 1534 1525 1542 1531 1541 1572 1568 1539 1557 1603 1578 1556 1574 1520 1524 1525 1544 1511 1537 1540 1592 1531 1549 1545 1523 1518 1482 1574 1558 1556 1571 1677 1585 1522 1574 1541 1552 1578 1596 1531 1571 1548 1551 1590 1548 1548 1548 1532 1563 1560 1519 1522 1564 1561 1575 1547 1497 1517 1539 1551 1569 1582 1546 1566 1557 1565 1595 1569 1532 1533 1563 1551 1583 1573 1506 1552 1544 1560 1580 1574 1579 1563 1526 1571 1586 1535 1526 1530 1480 1542 1554 1693 1543 1590 1581 1551 1560 1535 1515 1594 1565 1527 1582 1585 1545 1510 1557 1532 1568 1584 1568 1531 1570 1595 1542 1560 1574 1551 1554 1534 1509 1531 1556 1548 1541 1537 1567 1560 1563 1537 1549 1540 1595 1578 1602 1566 1547 1526 1544 1531 1582 1542 1584 1541 1578 1537 1581 1625 1530 1543 1480 1556 1490 1563 1595 1560 1505 1532 1572 1552 1588 1556 1572 1577 1612 1576 1580 1584 1588 1607 1596 1565 1560 1582 1558 1551 1554 1569 1578 1547 1529 1530 1566 1601 1582 1581 1496 1521 1557 1545 1571 1558 1546 1564 1541 1515 1620 1551 1539 1600 1545 1563 1550 1770 1538 1602 1661 1600 1535 1646 1540 1544 1550 1578 1585 1571 1592 1515 1577 1560 1609 1552 1537 1569 1582 1559 1547 1589 1535 1535 1579 1600 1609 1575 1553 1547 1534 1558 1553 1547 1581 1600 1609 1593 1590 1549 1561 1603 1588 1566 1534 1571 1545 1543 1557 1542 1569 1614 1588 1556 1540 1539 1573 1557 1549 1558 1541 1566 1525 1587 1706 1622 1566 1576 1593 1495 1587 1599 1550 1565 1562 1580 1563 1555 1591 1567 1525 1585 1567 1548 1579 1584 1568 1587 1588 1550 1540 1608 1582 1534 1562 1612 1621 1620 1596 1577 1594 1559 1595 1642 1588 1572 1565 1588 1524 1537 1563 1554 1647 1626 1610 1564 1618 1631 1580 1554 1538 1599 1575 1593 1551 1573 1545 1581 1586 1596 1542 1576 1568 1592 1569 1557 1571 1605 1588 1581 1566 1575 1584 1574 1583 1552 1570 1556 1579 1578 1564 1599 1578 1594 1568 1604 1567 1558 1568 1592 1601 1554 1546 1556 1576 1549 1574 1605 1586 1541 1549 1565 1594 1562 1632 1555 1571 1640 1592 1597 1510 1574 1609 1527 1505 1571 1549 1562 1585 1546 1537 1567 1585 1547 1545 1552 1562 1553 1587 1600 1612 1587 1551 1566 1579 1579 1582 1542 1556 1577 1580 1553 1541 1547 1592 1571 1555 1562 1604 1593 1582 1538 1552 1574 1599 1572 1572 1532 1569 1571 1516 1569 1684 1592 1624 1579 1606 1617 1556 1568 1566 1557 1590 1538 1578 1609 1549 1565 1552 1571 1564 1568 1573 1552 1555 1566 1564 1552 1566 1605 1629 1602 1607 1605 1593 1573 1549 1591 1605 1585 1587 1587 1573 1573 1588 1580 1599 1595 1515 1493 1582 1565 1539 1552 1557 1557 1559 1595 1605 1578 1578 1590 1561 1553 1583 1601 1545 1565 1594 1571 1562 1518 1609 1626 1569 1599 1589 1574 1584 1567 1549 1563 1567 1572 1584 1601 1611 1599 1558 1549 1547 1535 1571 1582 1562 1582 1571 1596 1602 1586 1610 1599 1596 1558 1594 1596 1619 1588 1519 1577 1546 1597 1598 1560 1608 1586 1606 1615 1595 1566 1574 1572 1582 1540 1610 1571 1590 1640 1592 1575 1597 1543 1566 1608 1571 1612 1592 1585 1573 1585 1573 1594 1592 1604 1624 1609 1613 1637 1612 1569 1565 1574 1598 1627 1584 1589 1573 1593 1620 1612 1580 1727 1635 1609 1602 1567 1574 1574 1608 1617 1622 1603 1583 1569 1617 1624 1617 1634 1639 1577 1642 1639 1558 1507 1613 1635 1601 1622 1593 1622 1647 1618 1594 1604 1653 1644 1583 1581 1599 1585 1566 1586 1644 1669 1640 1600 1601 1652 1630 1619 1642 1619 1642 1660 1626 1635 1635 1641 1624 1598 1615 1627 1650 1681 1613 1607 1661 1740 1678 1652 1630 1642 1664 1607 1613 1565 1607 1592 1633 1593 1606 1661 1626 1591 1543 1614 1654 1575 1596 1614 1649 1646 1660 1649 1626 1646 1656 1680 1678 1675 1643 1610 1671 1693 1628 1602 1615 1602 1623 1657 1654 1642 1634 1633 1628 1638 1642 1617 1641 1665 1628 1611 1599 1633 1652 1641 1676 1645 1670 1667 1666 1608 1642 1686 1699 1677 1654 1646 1643 1660 1629 1659 1663 1704 1679 1723 1698 1660 1673 1642 1635 1676 1661 1668 1693 1737 1773 1780 1838 1885 1902 1903 1985 2016 2025 2058 2027 2018 2092 2175 2171 2220 2302 2353 2420 2590 2810 3123 3677 4616 6078 8582 12621 18325 25724 30736 29280 24198 18497 13440 9666 7181 5678 4595 3835 3348 2962 2779 2328 2497 2412 2214 2300 2183 2137 2065 2027 2003 2015 1932 1859 1943 1842 1799 1753 1659 1701 1765 1730 1707 1687 1681 1752 1752 1689 1746 1740 1701 1705 1720 1679 1771 1715 1735 1734 1665 1648 1738 1640 1635 1641 1704 1649 1663 1726 1701 1691 1672 1657 1678 1696 1643 1645 1690 1615 1646 1650 1623 1693 1649 1634 1670 1647 1653 1632 1637 1620 1626 1622 1610 1645 1672 1655 1637 1670 1668 1638 1672 1656 1631 1631 1649 1638 1617 1679 1671 1669 1655 1609 1646 1606 1638 1645 1659 1655 1658 1707 1646 1619 1669 1595 1657 1651 1797 1691 1612 1606 1637 1682 1668 1652 1665 1620 1672 1594 1639 1636 1641 1616 1644 1647 1632 1649 1612 1573 1588 1641 1671 1615 1586 1603 1583 1618 1636 1598 1603 1625 1665 1647 1586 1600 1615 1655 1640 1620 1637 1620 1626 1619 1605 1609 1675 1636 1618 1596 1574 1588 1602 1652 1603 1660 1620 1662 1670 1623 1614 1585 1608 1598 1609 1660 1648 1604 1654 1636 1591 1620 1633 1659 1586 1619 1603 1653 1661 1626 1601 1600 1633 1638 1607 1615 1634 1668 1652 1645 1640 1666 1649 1615 1636 1600 1585 1597 1670 1658 1639 1621 1653 1589 1596 1570 1620 1634 1660 1634 1635 1665 1647 1621 1635 1631 1602 1593 1575 1592 1591 1682 1629 1634 1612 1624 1656 1612 1587 1607 1620 1616 1630 1585 1612 1640 1663 1632 1606 1618 1601 1594 1606 1595 1609 1653 1638 1637 1649 1619 1624 1608 1619 1640 1623 1648 1652 1602 1620 1597 1601 1572 1599 1665 1656 1623 1645 1553 1650 1671 1630 1592 1645 1611 1647 1641 1654 1523 1583 1647 1629 1667 1657 1620 1653 1616 1663 1686 1655 1600 1637 1602 1610 1612 1642 1672 1678 1648 1641 1635 1601 1609 1605 1599 1625 1617 1627 1628 1631 1659 1653 1687 1644 1646 1635 1646 1633 1651 1616 1650 1659 1633 1629 1603 1622 1590 1579 1526 1584</intensities>
			</dataPoints>
			<nonAmbientPoints type="Temperature" unit="K">
				<measurementTimes unit="seconds" deltaTime="1">0</measurementTimes>
				<nonAmbientValues>298.000</nonAmbientValues>
			</nonAmbientPoints>
		</scan>
	</xrdMeasurement>
</xrdMeasurements>