File: Result/Raw data/XRD_550C_raw/SAMPLE_6_COPPER_45mins_550C.XRDML striped k alpha 2.csv
[Measurement conditions]
Sample identification,
Comment - 1,"Configuration=Flat Sample Stage, Owner=User-1, Creation date=3/25/2015 2:10:01 PM"
Comment - 2,"Goniometer=PW3050/60 (Theta/Theta); Minimum step size 2Theta:0.001; Minimum step size Omega:0.001"
Comment - 3,"Sample stage=PW3071/xx Bracket"
Comment - 4,"Diffractometer system=XPERT-PRO"
Comment - 5,"Measurement program=C:\PANalytical\Data Collector\Programs\Flat sample Scan.xrdmp, Identifier={A9F6D0C0-202E-4C59-A4F1-A5BA86123012}"
Comment - 6,""
Anode material,Cu
K-Alpha1 wavelength,1.5405980
K-Alpha2 wavelength,1.5444260
Ratio K-Alpha2/K-Alpha1,0.000
Divergence slit,Fixed,0.500
Receiving slit,0.10
Monochromator used,NO
Generator voltage, 40
Tube current, 30
File date and time,27/Feb/2020 18:08
Unit cell,
h k l, 0 0 0
Temperature [K],298
Scan axis,Gonio
Scan range,19.9995,79.9925
Scan step size,0.0170000
No. of points, 3529
Scan type,CONTINUOUS
Time per step,34.925
[Scan points]
Angle,Intensity
20.0090,654.2
20.0600,693.5
20.1110,679.4
20.1620,664.1
20.2130,654.9
20.2640,675.4
20.3150,670.4
20.3660,646.6
20.4170,697.2
20.4680,686.8
20.5190,658.4
20.5700,664.0
20.6210,681.5
20.6720,671.4
20.7230,694.6
20.7740,678.1
20.8250,688.3
20.8760,670.1
20.9270,759.4
20.9780,672.8
21.0290,747.2
21.0800,667.1
21.1310,676.2
21.1820,672.1
21.2330,637.6
21.2840,686.6
21.3350,694.4
21.3860,683.4
21.4370,682.6
21.4880,663.5
21.5390,649.9
21.5900,675.7
21.6410,678.4
21.6920,692.3
21.7430,682.6
21.7940,672.4
21.8450,665.6
21.8960,682.6
21.9470,669.1
21.9980,730.5
22.0490,647.7
22.1000,691.8
22.1510,689.5
22.2020,679.1
22.2530,693.8
22.3040,694.1
22.3550,653.1
22.4060,677.8
22.4570,728.9
22.5080,661.1
22.5590,678.9
22.6100,677.0
22.6610,679.8
22.7120,703.1
22.7630,685.1
22.8140,709.4
22.8650,662.1
22.9160,700.8
22.9670,668.6
23.0180,686.8
23.0690,694.5
23.1200,713.9
23.1710,711.6
23.2220,707.5
23.2730,719.2
23.3240,720.1
23.3750,680.8
23.4260,672.0
23.4770,691.1
23.5280,690.9
23.5790,674.5
23.6300,660.3
23.6810,666.3
23.7320,697.1
23.7830,694.7
23.8340,694.8
23.8850,692.9
23.9360,710.1
23.9870,685.2
24.0380,690.4
24.0890,685.5
24.1400,716.2
24.1910,690.9
24.2420,671.2
24.2930,695.2
24.3440,730.6
24.3950,701.9
24.4460,729.3
24.4970,706.6
24.5480,727.6
24.5990,706.6
24.6500,707.1
24.7010,709.6
24.7520,737.8
24.8030,727.7
24.8540,703.5
24.9050,725.2
24.9560,709.4
25.0070,695.2
25.0580,729.2
25.1090,718.3
25.1600,694.4
25.2110,715.4
25.2620,697.2
25.3130,705.3
25.3640,725.6
25.4150,734.2
25.4660,733.1
25.5170,701.8
25.5680,710.5
25.6190,714.7
25.6700,712.1
25.7210,719.5
25.7720,761.3
25.8230,735.8
25.8740,714.9
25.9250,761.8
25.9760,717.9
26.0270,712.0
26.0780,743.4
26.1290,733.3
26.1800,735.5
26.2310,713.2
26.2820,724.4
26.3330,714.5
26.3840,745.8
26.4350,720.2
26.4860,718.9
26.5370,733.7
26.5880,706.6
26.6390,712.8
26.6900,733.7
26.7410,731.2
26.7920,735.9
26.8430,749.9
26.8940,722.4
26.9450,716.8
26.9960,716.9
27.0470,763.1
27.0980,769.1
27.1490,726.8
27.2000,733.2
27.2510,753.5
27.3020,766.2
27.3530,801.6
27.4040,770.2
27.4550,734.0
27.5060,724.4
27.5570,732.7
27.6080,728.6
27.6590,760.0
27.7100,738.0
27.7610,776.9
27.8120,774.2
27.8630,753.2
27.9140,745.6
27.9650,746.5
28.0160,759.2
28.0670,751.6
28.1180,744.9
28.1690,765.5
28.2200,755.3
28.2710,738.8
28.3220,783.9
28.3730,762.2
28.4240,744.1
28.4750,752.6
28.5260,749.1
28.5770,756.8
28.6280,748.4
28.6790,792.5
28.7300,780.2
28.7810,763.2
28.8320,780.9
28.8830,730.2
28.9340,783.5
28.9850,748.6
29.0360,775.4
29.0870,772.2
29.1380,793.1
29.1890,779.4
29.2400,773.1
29.2910,806.3
29.3420,784.6
29.3930,751.1
29.4440,798.1
29.4950,774.5
29.5460,764.9
29.5970,753.3
29.6480,798.1
29.6990,766.4
29.7500,752.5
29.8010,794.9
29.8520,735.1
29.9030,756.7
29.9540,802.6
30.0050,779.5
30.0560,762.2
30.1070,758.6
30.1580,784.9
30.2090,769.8
30.2600,774.1
30.3110,770.0
30.3620,763.9
30.4130,740.8
30.4640,758.4
30.5150,815.1
30.5660,780.7
30.6170,796.4
30.6680,812.5
30.7190,772.8
30.7700,759.6
30.8210,783.6
30.8720,754.0
30.9230,786.4
30.9740,760.3
31.0250,745.5
31.0760,838.8
31.1270,769.8
31.1780,782.5
31.2290,795.9
31.2800,771.4
31.3310,802.4
31.3820,780.3
31.4330,762.1
31.4840,772.6
31.5350,781.9
31.5860,815.5
31.6370,752.2
31.6880,794.8
31.7390,777.4
31.7900,792.0
31.8410,761.8
31.8920,786.3
31.9430,796.6
31.9940,781.5
32.0450,805.5
32.0960,757.4
32.1470,809.9
32.1980,769.9
32.2490,799.4
32.3000,765.4
32.3510,781.9
32.4020,757.2
32.4530,797.6
32.5040,796.2
32.5550,810.9
32.6060,802.0
32.6570,778.0
32.7080,813.2
32.7590,805.2
32.8100,832.3
32.8610,785.7
32.9120,803.5
32.9630,803.5
33.0140,795.8
33.0650,800.4
33.1160,809.4
33.1670,829.7
33.2180,817.7
33.2690,802.1
33.3200,811.3
33.3710,820.0
33.4220,803.2
33.4730,794.1
33.5240,814.6
33.5750,833.7
33.6260,778.5
33.6770,817.7
33.7280,792.1
33.7790,787.8
33.8300,851.4
33.8810,789.8
33.9320,827.5
33.9830,796.8
34.0340,779.4
34.0850,795.8
34.1360,818.4
34.1870,797.9
34.2380,785.6
34.2890,786.4
34.3400,796.4
34.3910,797.8
34.4420,820.1
34.4930,800.2
34.5440,837.7
34.5950,806.8
34.6460,794.6
34.6970,780.8
34.7480,792.8
34.7990,831.6
34.8500,797.5
34.9010,813.4
34.9520,798.8
35.0030,790.7
35.0540,827.1
35.1050,835.5
35.1560,810.1
35.2070,821.2
35.2580,831.6
35.3090,813.5
35.3600,840.3
35.4110,859.4
35.4620,835.8
35.5130,836.9
35.5640,856.8
35.6150,829.1
35.6660,866.2
35.7170,842.1
35.7680,823.3
35.8190,815.3
35.8700,826.3
35.9210,818.4
35.9720,835.7
36.0230,830.9
36.0740,831.5
36.1250,819.4
36.1760,833.9
36.2270,831.9
36.2780,830.6
36.3290,822.6
36.3800,800.9
36.4310,856.7
36.4820,807.6
36.5330,846.8
36.5840,858.8
36.6350,867.4
36.6860,820.2
36.7370,849.4
36.7880,809.4
36.8390,804.6
36.8900,866.0
36.9410,827.9
36.9920,841.8
37.0430,874.8
37.0940,873.2
37.1450,821.0
37.1960,822.9
37.2470,801.2
37.2980,842.7
37.3490,831.6
37.4000,846.1
37.4510,846.9
37.5020,829.4
37.5530,862.6
37.6040,833.9
37.6550,820.2
37.7060,817.4
37.7570,879.9
37.8080,822.9
37.8590,816.4
37.9100,829.0
37.9610,856.9
38.0120,850.0
38.0630,838.0
38.1140,829.1
38.1650,837.5
38.2160,854.2
38.2670,891.3
38.3180,855.8
38.3690,847.5
38.4200,846.6
38.4710,834.9
38.5220,849.8
38.5730,894.8
38.6240,839.7
38.6750,881.5
38.7260,826.3
38.7770,840.9
38.8280,890.9
38.8790,869.6
38.9300,862.7
38.9810,833.3
39.0320,828.4
39.0830,872.4
39.1340,825.6
39.1850,842.7
39.2360,880.4
39.2870,880.7
39.3380,861.4
39.3890,852.0
39.4400,853.9
39.4910,845.8
39.5420,839.2
39.5930,862.2
39.6440,853.2
39.6950,876.6
39.7460,856.1
39.7970,896.7
39.8480,870.0
39.8990,866.6
39.9500,879.5
40.0010,885.8
40.0520,841.7
40.1030,866.9
40.1540,877.2
40.2050,842.3
40.2560,881.6
40.3070,867.6
40.3580,888.3
40.4090,880.2
40.4600,877.7
40.5110,851.8
40.5620,850.3
40.6130,876.6
40.6640,886.9
40.7150,894.2
40.7660,867.6
40.8170,889.2
40.8680,902.2
40.9190,863.1
40.9700,944.3
41.0210,896.7
41.0720,872.4
41.1230,879.4
41.1740,877.4
41.2250,846.8
41.2760,861.1
41.3270,855.9
41.3780,904.7
41.4290,887.8
41.4800,880.8
41.5310,848.8
41.5820,925.8
41.6330,888.3
41.6840,879.7
41.7350,951.7
41.7860,893.1
41.8370,919.8
41.8880,939.4
41.9390,896.6
41.9900,896.1
42.0410,909.6
42.0920,936.1
42.1430,893.8
42.1940,886.1
42.2450,935.7
42.2960,903.0
42.3470,919.6
42.3980,872.6
42.4490,933.3
42.5000,923.9
42.5510,956.7
42.6020,914.9
42.6530,886.0
42.7040,902.2
42.7550,930.6
42.8060,937.0
42.8570,961.2
42.9080,941.5
42.9590,1050.9
43.0100,1138.5
43.0610,1207.8
43.1120,1322.6
43.1630,1965.2
43.2140,5690.1
43.2650,16033.6
43.3160,6605.3
43.3670,2393.6
43.4180,1275.7
43.4690,1110.9
43.5200,1115.0
43.5710,1025.9
43.6220,972.8
43.6730,959.0
43.7240,1032.3
43.7750,951.4
43.8260,919.5
43.8770,938.8
43.9280,934.6
43.9790,937.9
44.0300,959.6
44.0810,929.4
44.1320,939.5
44.1830,925.2
44.2340,916.6
44.2850,926.6
44.3360,952.1
44.3870,923.9
44.4380,897.2
44.4890,910.1
44.5400,966.5
44.5910,901.6
44.6420,929.3
44.6930,928.5
44.7440,925.8
44.7950,934.4
44.8460,924.9
44.8970,958.7
44.9480,934.1
44.9990,915.3
45.0500,895.6
45.1010,944.4
45.1520,941.2
45.2030,934.4
45.2540,960.2
45.3050,959.5
45.3560,936.2
45.4070,933.2
45.4580,927.5
45.5090,937.1
45.5600,942.1
45.6110,891.1
45.6620,931.0
45.7130,922.7
45.7640,951.6
45.8150,937.4
45.8660,934.7
45.9170,916.1
45.9680,904.7
46.0190,983.5
46.0700,943.1
46.1210,918.4
46.1720,927.8
46.2230,938.8
46.2740,958.9
46.3250,934.5
46.3760,928.8
46.4270,924.5
46.4780,924.9
46.5290,906.2
46.5800,919.2
46.6310,953.6
46.6820,926.1
46.7330,949.1
46.7840,896.6
46.8350,945.2
46.8860,925.8
46.9370,933.2
46.9880,922.8
47.0390,927.5
47.0900,924.6
47.1410,959.8
47.1920,910.2
47.2430,960.9
47.2940,944.2
47.3450,927.4
47.3960,917.3
47.4470,967.5
47.4980,954.0
47.5490,946.5
47.6000,926.0
47.6510,945.2
47.7020,934.3
47.7530,944.2
47.8040,924.2
47.8550,917.6
47.9060,929.9
47.9570,971.9
48.0080,895.6
48.0590,936.8
48.1100,946.2
48.1610,959.8
48.2120,955.9
48.2630,955.2
48.3140,963.4
48.3650,920.8
48.4160,915.6
48.4670,923.1
48.5180,911.1
48.5690,1015.5
48.6200,1002.7
48.6710,968.8
48.7220,997.6
48.7730,962.3
48.8240,966.3
48.8750,1004.2
48.9260,980.7
48.9770,989.2
49.0280,1018.1
49.0790,998.5
49.1300,1001.9
49.1810,1039.1
49.2320,1001.2
49.2830,1006.5
49.3340,987.2
49.3850,1006.2
49.4360,995.1
49.4870,1023.7
49.5380,1000.2
49.5890,981.9
49.6400,1036.8
49.6910,1014.8
49.7420,1023.4
49.7930,1040.4
49.8440,1015.2
49.8950,1068.6
49.9460,1072.1
49.9970,1083.0
50.0480,1184.2
50.0990,1496.1
50.1500,1779.8
50.2010,1898.4
50.2520,2573.2
50.3030,6879.6
50.3540,30217.3
50.4050,31782.9
50.4560,7800.5
50.5070,2912.6
50.5580,1960.6
50.6090,1601.3
50.6600,1144.2
50.7110,1184.2
50.7620,1044.3
50.8130,1184.8
50.8640,1071.3
50.9150,1079.4
50.9660,1078.5
51.0170,1024.6
51.0680,1044.2
51.1190,1004.6
51.1700,1021.4
51.2210,1002.1
51.2720,994.4
51.3230,1000.5
51.3740,991.4
51.4250,1024.3
51.4760,975.7
51.5270,1000.2
51.5780,987.5
51.6290,989.5
51.6800,952.3
51.7310,1017.4
51.7820,992.9
51.8330,980.4
51.8840,957.5
51.9350,1011.5
51.9860,996.2
52.0370,983.5
52.0880,1015.8
52.1390,983.5
52.1900,973.0
52.2410,1009.2
52.2920,960.0
52.3430,979.2
52.3940,948.9
52.4450,969.1
52.4960,990.1
52.5470,962.1
52.5980,968.4
52.6490,948.8
52.7000,966.2
52.7510,1012.1
52.8020,990.4
52.8530,968.2
52.9040,962.5
52.9550,974.8
53.0060,994.9
53.0570,957.8
53.1080,972.5
53.1590,955.2
53.2100,906.5
53.2610,962.4
53.3120,941.9
53.3630,978.5
53.4140,977.1
53.4650,955.2
53.5160,967.6
53.5670,961.5
53.6180,930.2
53.6690,952.2
53.7200,967.9
53.7710,989.9
53.8220,947.4
53.8730,989.6
53.9240,955.8
53.9750,957.2
54.0260,1002.2
54.0770,978.2
54.1280,976.1
54.1790,961.6
54.2300,970.9
54.2810,1001.5
54.3320,966.2
54.3830,940.8
54.4340,937.6
54.4850,983.2
54.5360,953.4
54.5870,963.5
54.6380,939.3
54.6890,1009.2
54.7400,967.3
54.7910,992.6
54.8420,966.6
54.8930,967.5
54.9440,984.1
54.9950,968.1
55.0460,963.7
55.0970,940.7
55.1480,979.4
55.1990,951.9
55.2500,964.8
55.3010,999.5
55.3520,949.6
55.4030,921.2
55.4540,986.8
55.5050,978.4
55.5560,977.0
55.6070,944.9
55.6580,962.4
55.7090,976.1
55.7600,955.1
55.8110,944.6
55.8620,965.5
55.9130,961.9
55.9640,953.8
56.0150,955.9
56.0660,1005.1
56.1170,986.2
56.1680,1013.9
56.2190,937.6
56.2700,950.4
56.3210,995.2
56.3720,955.6
56.4230,1006.9
56.4740,922.3
56.5250,966.2
56.5760,956.5
56.6270,956.5
56.6780,944.4
56.7290,958.1
56.7800,972.9
56.8310,949.4
56.8820,971.5
56.9330,958.0
56.9840,964.1
57.0350,949.6
57.0860,968.4
57.1370,1014.4
57.1880,969.5
57.2390,938.4
57.2900,951.4
57.3410,946.6
57.3920,971.0
57.4430,978.4
57.4940,969.1
57.5450,980.7
57.5960,949.4
57.6470,960.2
57.6980,1005.1
57.7490,949.0
57.8000,972.2
57.8510,953.0
57.9020,960.6
57.9530,978.9
58.0040,978.8
58.0550,989.3
58.1060,976.9
58.1570,942.1
58.2080,1004.4
58.2590,957.6
58.3100,991.7
58.3610,942.7
58.4120,940.5
58.4630,948.6
58.5140,1009.4
58.5650,951.9
58.6160,978.6
58.6670,956.8
58.7180,966.1
58.7690,934.7
58.8200,972.9
58.8710,981.7
58.9220,952.9
58.9730,976.4
59.0240,993.6
59.0750,946.6
59.1260,977.9
59.1770,926.1
59.2280,936.9
59.2790,1000.2
59.3300,922.6
59.3810,955.1
59.4320,934.1
59.4830,986.1
59.5340,960.8
59.5850,950.2
59.6360,932.2
59.6870,951.6
59.7380,965.4
59.7890,982.4
59.8400,1010.2
59.8910,971.8
59.9420,970.5
59.9930,975.8
60.0440,966.4
60.0950,960.2
60.1460,948.1
60.1970,953.6
60.2480,977.5
60.2990,977.4
60.3500,977.4
60.4010,1001.8
60.4520,1000.6
60.5030,972.2
60.5540,941.0
60.6050,968.1
60.6560,966.6
60.7070,987.6
60.7580,965.9
60.8090,986.9
60.8600,987.5
60.9110,974.1
60.9620,962.6
61.0130,944.4
61.0640,1025.8
61.1150,967.2
61.1660,1010.6
61.2170,1006.4
61.2680,984.6
61.3190,986.6
61.3700,979.9
61.4210,958.3
61.4720,1001.2
61.5230,997.0
61.5740,985.8
61.6250,956.6
61.6760,950.9
61.7270,939.4
61.7780,1001.8
61.8290,982.9
61.8800,954.1
61.9310,965.6
61.9820,962.9
62.0330,975.1
62.0840,974.4
62.1350,997.6
62.1860,920.1
62.2370,976.8
62.2880,980.7
62.3390,935.2
62.3900,948.0
62.4410,991.4
62.4920,951.1
62.5430,963.4
62.5940,990.6
62.6450,957.9
62.6960,1019.5
62.7470,997.9
62.7980,966.8
62.8490,956.4
62.9000,970.6
62.9510,1002.2
63.0020,993.7
63.0530,965.1
63.1040,956.6
63.1550,951.6
63.2060,975.4
63.2570,1016.8
63.3080,961.4
63.3590,993.2
63.4100,961.4
63.4610,972.4
63.5120,954.1
63.5630,1008.2
63.6140,989.3
63.6650,964.8
63.7160,967.8
63.7670,996.2
63.8180,998.8
63.8690,999.2
63.9200,994.5
63.9710,984.6
64.0220,959.1
64.0730,967.6
64.1240,961.7
64.1750,972.6
64.2260,981.3
64.2770,1011.1
64.3280,1010.2
64.3790,1010.0
64.4300,971.3
64.4810,950.8
64.5320,964.3
64.5830,954.0
64.6340,981.4
64.6850,990.2
64.7360,989.4
64.7870,980.1
64.8380,997.9
64.8890,967.2
64.9400,1009.1
64.9910,980.6
65.0420,959.6
65.0930,980.9
65.1440,973.2
65.1950,968.4
65.2460,956.2
65.2970,989.1
65.3480,989.9
65.3990,999.9
65.4500,965.4
65.5010,975.6
65.5520,1013.4
65.6030,1025.5
65.6540,999.5
65.7050,966.5
65.7560,963.9
65.8070,1020.8
65.8580,998.3
65.9090,988.9
65.9600,996.6
66.0110,969.8
66.0620,1011.8
66.1130,1015.1
66.1640,997.6
66.2150,951.2
66.2660,988.4
66.3170,986.0
66.3680,1000.8
66.4190,938.5
66.4700,967.9
66.5210,1001.5
66.5720,991.1
66.6230,1020.8
66.6740,973.7
66.7250,969.1
66.7760,974.3
66.8270,967.8
66.8780,996.1
66.9290,1019.8
66.9800,1033.8
67.0310,972.6
67.0820,990.4
67.1330,1046.0
67.1840,1009.2
67.2350,1014.9
67.2860,1003.8
67.3370,990.5
67.3880,971.1
67.4390,1021.1
67.4900,1021.3
67.5410,1026.2
67.5920,1013.8
67.6430,990.3
67.6940,1005.5
67.7450,993.6
67.7960,972.8
67.8470,978.8
67.8980,1008.4
67.9490,1017.5
68.0000,974.2
68.0510,981.2
68.1020,1006.6
68.1530,1013.1
68.2040,1008.2
68.2550,1038.9
68.3060,1010.5
68.3570,997.3
68.4080,1014.9
68.4590,1014.9
68.5100,984.6
68.5610,1017.8
68.6120,958.6
68.6630,994.8
68.7140,983.5
68.7650,999.8
68.8160,1020.6
68.8670,999.2
68.9180,1014.9
68.9690,970.5
69.0200,990.6
69.0710,978.0
69.1220,1003.5
69.1730,976.4
69.2240,1008.4
69.2750,1002.7
69.3260,962.5
69.3770,1012.3
69.4280,1001.2
69.4790,1003.5
69.5300,998.5
69.5810,1001.5
69.6320,1007.5
69.6830,1025.7
69.7340,973.4
69.7850,1010.3
69.8360,1024.6
69.8870,1014.4
69.9380,1013.6
69.9890,998.8
70.0400,995.2
70.0910,1004.9
70.1420,1027.6
70.1930,999.8
70.2440,1033.5
70.2950,1013.4
70.3460,981.8
70.3970,1038.2
70.4480,1022.2
70.4990,1031.1
70.5500,1039.4
70.6010,1001.2
70.6520,1010.2
70.7030,1005.4
70.7540,1012.6
70.8050,1001.5
70.8560,1015.1
70.9070,1011.1
70.9580,1024.7
71.0090,999.9
71.0600,1008.6
71.1110,1004.1
71.1620,989.7
71.2130,1031.5
71.2640,1014.2
71.3150,1023.2
71.3660,1001.0
71.4170,1006.3
71.4680,999.8
71.5190,1020.4
71.5700,1038.1
71.6210,1053.6
71.6720,1009.0
71.7230,1025.5
71.7740,1043.2
71.8250,1036.0
71.8760,1040.4
71.9270,1060.8
71.9780,1052.3
72.0290,1025.0
72.0800,1052.7
72.1310,1021.7
72.1820,1027.5
72.2330,1024.7
72.2840,1064.3
72.3350,1042.9
72.3860,1040.0
72.4370,1062.6
72.4880,1039.3
72.5390,1043.8
72.5900,1059.4
72.6410,1063.1
72.6920,1040.9
72.7430,1047.6
72.7940,1034.4
72.8450,1033.2
72.8960,1059.4
72.9470,1032.1
72.9980,1015.8
73.0490,1028.6
73.1000,1069.4
73.1510,1029.5
73.2020,1109.1
73.2530,1039.2
73.3040,1039.7
73.3550,1076.4
73.4060,1091.6
73.4570,1040.2
73.5080,1093.0
73.5590,1078.5
73.6100,1235.6
73.6610,1271.6
73.7120,1230.2
73.7630,1232.0
73.8140,1304.7
73.8650,1466.8
73.9160,2062.8
73.9670,5273.1
74.0180,18380.9
74.0690,10373.6
74.1200,3285.6
74.1710,1702.5
74.2220,1369.8
74.2730,1460.1
74.3240,1273.3
74.3750,1248.7
74.4260,1171.1
74.4770,1194.4
74.5280,1129.2
74.5790,1121.3
74.6300,1110.3
74.6810,1104.3
74.7320,1070.1
74.7830,1074.2
74.8340,1119.6
74.8850,1070.5
74.9360,1045.2
74.9870,1049.5
75.0380,1069.0
75.0890,1057.1
75.1400,1071.1
75.1910,1067.2
75.2420,1067.5
75.2930,1054.7
75.3440,1069.1
75.3950,1040.9
75.4460,1087.8
75.4970,1074.3
75.5480,1053.3
75.5990,1072.6
75.6500,1070.6
75.7010,1067.5
75.7520,1025.9
75.8030,1057.7
75.8540,1095.5
75.9050,1049.6
75.9560,1025.8
76.0070,1037.6
76.0580,1042.1
76.1090,1028.2
76.1600,1084.5
76.2110,1068.7
76.2620,1061.7
76.3130,1060.8
76.3640,1051.8
76.4150,1059.4
76.4660,1033.9
76.5170,1056.8
76.5680,1039.9
76.6190,1096.8
76.6700,1081.9
76.7210,1059.5
76.7720,1056.5
76.8230,1026.1
76.8740,1085.6
76.9250,1051.6
76.9760,1027.4
77.0270,1071.6
77.0780,1077.1
77.1290,1059.8
77.1800,1021.6
77.2310,1064.4
77.2820,1023.6
77.3330,1063.9
77.3840,1068.1
77.4350,1032.9
77.4860,1034.5
77.5370,1055.8
77.5880,1050.5
77.6390,1081.6
77.6900,1052.7
77.7410,1059.3
77.7920,1025.7
77.8430,1043.7
77.8940,1072.9
77.9450,1050.1
77.9960,1056.5
78.0470,1075.1
78.0980,1058.3
78.1490,1064.2
78.2000,1069.2
78.2510,1030.9
78.3020,1059.2
78.3530,1056.5
78.4040,1044.9
78.4550,1061.4
78.5060,1045.1
78.5570,1023.9
78.6080,1074.9
78.6590,1056.7
78.7100,1035.4
78.7610,1086.8
78.8120,1055.2
78.8630,1038.5
78.9140,1040.5
78.9650,1073.2
79.0160,1044.7
79.0670,1040.5
79.1180,1042.4
79.1690,1059.2
79.2200,1059.6
79.2710,1070.3
79.3220,1055.1
79.3730,1069.5
79.4240,1060.6
79.4750,1072.4
79.5260,1033.3
79.5770,1050.6
79.6280,1044.5
79.6790,1039.1
79.7300,1039.7
79.7810,1052.2
79.8320,1057.4
79.8830,1056.1
79.9340,1058.8
79.9680,1062.7